2024-05-04 15:37:59,996 DEBUG Starting new HTTPS connection (1): api.bybit.com:443
2024-05-04 15:38:00,332 DEBUG https://api.bybit.com:443 "GET /v5/market/kline?category=spot&symbol=BTCUSDT&interval=60&limit=300 HTTP/1.1" 200 28235
2024-05-04 15:38:00,344 DEBUG Starting new HTTPS connection (1): api.bybit.com:443
2024-05-04 15:38:00,636 DEBUG https://api.bybit.com:443 "GET /v5/market/kline?category=spot&symbol=BTCUSDT&interval=60&limit=300 HTTP/1.1" 200 28234
2024-05-04 15:38:00,901 DEBUG Starting new HTTP connection (1): 127.0.0.1:5000
2024-05-04 15:38:02,934 ERROR 60min tf   
Traceback (most recent call last):
  File "C:\Users\Andrew the master\Documents\GitHub\TraidingAlgorithm\venv\Lib\site-packages\urllib3\connection.py", line 203, in _new_conn
    sock = connection.create_connection(
           ^^^^^^^^^^^^^^^^^^^^^^^^^^^^^
  File "C:\Users\Andrew the master\Documents\GitHub\TraidingAlgorithm\venv\Lib\site-packages\urllib3\util\connection.py", line 85, in create_connection
    raise err
  File "C:\Users\Andrew the master\Documents\GitHub\TraidingAlgorithm\venv\Lib\site-packages\urllib3\util\connection.py", line 73, in create_connection
    sock.connect(sa)
ConnectionRefusedError: [WinError 10061] No connection could be made because the target machine actively refused it

The above exception was the direct cause of the following exception:

Traceback (most recent call last):
  File "C:\Users\Andrew the master\Documents\GitHub\TraidingAlgorithm\venv\Lib\site-packages\urllib3\connectionpool.py", line 790, in urlopen
    response = self._make_request(
               ^^^^^^^^^^^^^^^^^^^
  File "C:\Users\Andrew the master\Documents\GitHub\TraidingAlgorithm\venv\Lib\site-packages\urllib3\connectionpool.py", line 496, in _make_request
    conn.request(
  File "C:\Users\Andrew the master\Documents\GitHub\TraidingAlgorithm\venv\Lib\site-packages\urllib3\connection.py", line 395, in request
    self.endheaders()
  File "C:\Users\Andrew the master\AppData\Local\Programs\Python\Python311\Lib\http\client.py", line 1278, in endheaders
    self._send_output(message_body, encode_chunked=encode_chunked)
  File "C:\Users\Andrew the master\AppData\Local\Programs\Python\Python311\Lib\http\client.py", line 1038, in _send_output
    self.send(msg)
  File "C:\Users\Andrew the master\AppData\Local\Programs\Python\Python311\Lib\http\client.py", line 976, in send
    self.connect()
  File "C:\Users\Andrew the master\Documents\GitHub\TraidingAlgorithm\venv\Lib\site-packages\urllib3\connection.py", line 243, in connect
    self.sock = self._new_conn()
                ^^^^^^^^^^^^^^^^
  File "C:\Users\Andrew the master\Documents\GitHub\TraidingAlgorithm\venv\Lib\site-packages\urllib3\connection.py", line 218, in _new_conn
    raise NewConnectionError(
urllib3.exceptions.NewConnectionError: <urllib3.connection.HTTPConnection object at 0x0000021AFF9F2610>: Failed to establish a new connection: [WinError 10061] No connection could be made because the target machine actively refused it

The above exception was the direct cause of the following exception:

Traceback (most recent call last):
  File "C:\Users\Andrew the master\Documents\GitHub\TraidingAlgorithm\venv\Lib\site-packages\requests\adapters.py", line 486, in send
    resp = conn.urlopen(
           ^^^^^^^^^^^^^
  File "C:\Users\Andrew the master\Documents\GitHub\TraidingAlgorithm\venv\Lib\site-packages\urllib3\connectionpool.py", line 844, in urlopen
    retries = retries.increment(
              ^^^^^^^^^^^^^^^^^^
  File "C:\Users\Andrew the master\Documents\GitHub\TraidingAlgorithm\venv\Lib\site-packages\urllib3\util\retry.py", line 515, in increment
    raise MaxRetryError(_pool, url, reason) from reason  # type: ignore[arg-type]
    ^^^^^^^^^^^^^^^^^^^^^^^^^^^^^^^^^^^^^^^^^^^^^^^^^^^
urllib3.exceptions.MaxRetryError: HTTPConnectionPool(host='127.0.0.1', port=5000): Max retries exceeded with url: /api/v1/engulfing-pattern (Caused by NewConnectionError('<urllib3.connection.HTTPConnection object at 0x0000021AFF9F2610>: Failed to establish a new connection: [WinError 10061] No connection could be made because the target machine actively refused it'))

During handling of the above exception, another exception occurred:

Traceback (most recent call last):
  File "c:\Users\Andrew the master\Documents\GitHub\TraidingAlgorithm\main.py", line 906, in BTCUSDT_60min
    getAlert(dft2, '60min', 'Close', 28, 'HeikinAshi', symb)
  File "c:\Users\Andrew the master\Documents\GitHub\TraidingAlgorithm\main.py", line 278, in getAlert
    requests.post(url=url, data=data, headers=headers)
  File "C:\Users\Andrew the master\Documents\GitHub\TraidingAlgorithm\venv\Lib\site-packages\requests\api.py", line 115, in post
    return request("post", url, data=data, json=json, **kwargs)
           ^^^^^^^^^^^^^^^^^^^^^^^^^^^^^^^^^^^^^^^^^^^^^^^^^^^^
  File "C:\Users\Andrew the master\Documents\GitHub\TraidingAlgorithm\venv\Lib\site-packages\requests\api.py", line 59, in request
    return session.request(method=method, url=url, **kwargs)
           ^^^^^^^^^^^^^^^^^^^^^^^^^^^^^^^^^^^^^^^^^^^^^^^^^
  File "C:\Users\Andrew the master\Documents\GitHub\TraidingAlgorithm\venv\Lib\site-packages\requests\sessions.py", line 589, in request
    resp = self.send(prep, **send_kwargs)
           ^^^^^^^^^^^^^^^^^^^^^^^^^^^^^^
  File "C:\Users\Andrew the master\Documents\GitHub\TraidingAlgorithm\venv\Lib\site-packages\requests\sessions.py", line 703, in send
    r = adapter.send(request, **kwargs)
        ^^^^^^^^^^^^^^^^^^^^^^^^^^^^^^^
  File "C:\Users\Andrew the master\Documents\GitHub\TraidingAlgorithm\venv\Lib\site-packages\requests\adapters.py", line 519, in send
    raise ConnectionError(e, request=request)
requests.exceptions.ConnectionError: HTTPConnectionPool(host='127.0.0.1', port=5000): Max retries exceeded with url: /api/v1/engulfing-pattern (Caused by NewConnectionError('<urllib3.connection.HTTPConnection object at 0x0000021AFF9F2610>: Failed to establish a new connection: [WinError 10061] No connection could be made because the target machine actively refused it'))
2024-05-04 15:38:02,940 DEBUG Starting new HTTPS connection (1): api.bybit.com:443
2024-05-04 15:38:03,247 DEBUG https://api.bybit.com:443 "GET /v5/market/kline?category=spot&symbol=ETHUSDT&interval=60&limit=300 HTTP/1.1" 200 None
2024-05-04 15:38:03,254 DEBUG Starting new HTTPS connection (1): api.bybit.com:443
2024-05-04 15:38:03,545 DEBUG https://api.bybit.com:443 "GET /v5/market/kline?category=spot&symbol=ETHUSDT&interval=60&limit=300 HTTP/1.1" 200 26779
2024-05-04 15:38:03,781 DEBUG Starting new HTTP connection (1): 127.0.0.1:5000
2024-05-04 15:38:05,830 ERROR 60min tf   
Traceback (most recent call last):
  File "C:\Users\Andrew the master\Documents\GitHub\TraidingAlgorithm\venv\Lib\site-packages\urllib3\connection.py", line 203, in _new_conn
    sock = connection.create_connection(
           ^^^^^^^^^^^^^^^^^^^^^^^^^^^^^
  File "C:\Users\Andrew the master\Documents\GitHub\TraidingAlgorithm\venv\Lib\site-packages\urllib3\util\connection.py", line 85, in create_connection
    raise err
  File "C:\Users\Andrew the master\Documents\GitHub\TraidingAlgorithm\venv\Lib\site-packages\urllib3\util\connection.py", line 73, in create_connection
    sock.connect(sa)
ConnectionRefusedError: [WinError 10061] No connection could be made because the target machine actively refused it

The above exception was the direct cause of the following exception:

Traceback (most recent call last):
  File "C:\Users\Andrew the master\Documents\GitHub\TraidingAlgorithm\venv\Lib\site-packages\urllib3\connectionpool.py", line 790, in urlopen
    response = self._make_request(
               ^^^^^^^^^^^^^^^^^^^
  File "C:\Users\Andrew the master\Documents\GitHub\TraidingAlgorithm\venv\Lib\site-packages\urllib3\connectionpool.py", line 496, in _make_request
    conn.request(
  File "C:\Users\Andrew the master\Documents\GitHub\TraidingAlgorithm\venv\Lib\site-packages\urllib3\connection.py", line 395, in request
    self.endheaders()
  File "C:\Users\Andrew the master\AppData\Local\Programs\Python\Python311\Lib\http\client.py", line 1278, in endheaders
    self._send_output(message_body, encode_chunked=encode_chunked)
  File "C:\Users\Andrew the master\AppData\Local\Programs\Python\Python311\Lib\http\client.py", line 1038, in _send_output
    self.send(msg)
  File "C:\Users\Andrew the master\AppData\Local\Programs\Python\Python311\Lib\http\client.py", line 976, in send
    self.connect()
  File "C:\Users\Andrew the master\Documents\GitHub\TraidingAlgorithm\venv\Lib\site-packages\urllib3\connection.py", line 243, in connect
    self.sock = self._new_conn()
                ^^^^^^^^^^^^^^^^
  File "C:\Users\Andrew the master\Documents\GitHub\TraidingAlgorithm\venv\Lib\site-packages\urllib3\connection.py", line 218, in _new_conn
    raise NewConnectionError(
urllib3.exceptions.NewConnectionError: <urllib3.connection.HTTPConnection object at 0x0000021AFFAC1E10>: Failed to establish a new connection: [WinError 10061] No connection could be made because the target machine actively refused it

The above exception was the direct cause of the following exception:

Traceback (most recent call last):
  File "C:\Users\Andrew the master\Documents\GitHub\TraidingAlgorithm\venv\Lib\site-packages\requests\adapters.py", line 486, in send
    resp = conn.urlopen(
           ^^^^^^^^^^^^^
  File "C:\Users\Andrew the master\Documents\GitHub\TraidingAlgorithm\venv\Lib\site-packages\urllib3\connectionpool.py", line 844, in urlopen
    retries = retries.increment(
              ^^^^^^^^^^^^^^^^^^
  File "C:\Users\Andrew the master\Documents\GitHub\TraidingAlgorithm\venv\Lib\site-packages\urllib3\util\retry.py", line 515, in increment
    raise MaxRetryError(_pool, url, reason) from reason  # type: ignore[arg-type]
    ^^^^^^^^^^^^^^^^^^^^^^^^^^^^^^^^^^^^^^^^^^^^^^^^^^^
urllib3.exceptions.MaxRetryError: HTTPConnectionPool(host='127.0.0.1', port=5000): Max retries exceeded with url: /api/v1/engulfing-pattern (Caused by NewConnectionError('<urllib3.connection.HTTPConnection object at 0x0000021AFFAC1E10>: Failed to establish a new connection: [WinError 10061] No connection could be made because the target machine actively refused it'))

During handling of the above exception, another exception occurred:

Traceback (most recent call last):
  File "c:\Users\Andrew the master\Documents\GitHub\TraidingAlgorithm\main.py", line 906, in BTCUSDT_60min
    getAlert(dft2, '60min', 'Close', 28, 'HeikinAshi', symb)
  File "c:\Users\Andrew the master\Documents\GitHub\TraidingAlgorithm\main.py", line 278, in getAlert
    requests.post(url=url, data=data, headers=headers)
  File "C:\Users\Andrew the master\Documents\GitHub\TraidingAlgorithm\venv\Lib\site-packages\requests\api.py", line 115, in post
    return request("post", url, data=data, json=json, **kwargs)
           ^^^^^^^^^^^^^^^^^^^^^^^^^^^^^^^^^^^^^^^^^^^^^^^^^^^^
  File "C:\Users\Andrew the master\Documents\GitHub\TraidingAlgorithm\venv\Lib\site-packages\requests\api.py", line 59, in request
    return session.request(method=method, url=url, **kwargs)
           ^^^^^^^^^^^^^^^^^^^^^^^^^^^^^^^^^^^^^^^^^^^^^^^^^
  File "C:\Users\Andrew the master\Documents\GitHub\TraidingAlgorithm\venv\Lib\site-packages\requests\sessions.py", line 589, in request
    resp = self.send(prep, **send_kwargs)
           ^^^^^^^^^^^^^^^^^^^^^^^^^^^^^^
  File "C:\Users\Andrew the master\Documents\GitHub\TraidingAlgorithm\venv\Lib\site-packages\requests\sessions.py", line 703, in send
    r = adapter.send(request, **kwargs)
        ^^^^^^^^^^^^^^^^^^^^^^^^^^^^^^^
  File "C:\Users\Andrew the master\Documents\GitHub\TraidingAlgorithm\venv\Lib\site-packages\requests\adapters.py", line 519, in send
    raise ConnectionError(e, request=request)
requests.exceptions.ConnectionError: HTTPConnectionPool(host='127.0.0.1', port=5000): Max retries exceeded with url: /api/v1/engulfing-pattern (Caused by NewConnectionError('<urllib3.connection.HTTPConnection object at 0x0000021AFFAC1E10>: Failed to establish a new connection: [WinError 10061] No connection could be made because the target machine actively refused it'))
2024-05-04 15:38:05,834 DEBUG Starting new HTTPS connection (1): api.bybit.com:443
2024-05-04 15:38:06,128 DEBUG https://api.bybit.com:443 "GET /v5/market/kline?category=spot&symbol=MNTUSDT&interval=60&limit=300 HTTP/1.1" 200 25054
2024-05-04 15:38:06,342 DEBUG Starting new HTTPS connection (1): api.bybit.com:443
2024-05-04 15:38:06,631 DEBUG https://api.bybit.com:443 "GET /v5/market/kline?category=spot&symbol=MNTUSDT&interval=60&limit=300 HTTP/1.1" 200 25053
2024-05-04 15:38:06,948 DEBUG Starting new HTTP connection (1): 127.0.0.1:5000
2024-05-04 15:38:08,988 ERROR 60min tf   
Traceback (most recent call last):
  File "C:\Users\Andrew the master\Documents\GitHub\TraidingAlgorithm\venv\Lib\site-packages\urllib3\connection.py", line 203, in _new_conn
    sock = connection.create_connection(
           ^^^^^^^^^^^^^^^^^^^^^^^^^^^^^
  File "C:\Users\Andrew the master\Documents\GitHub\TraidingAlgorithm\venv\Lib\site-packages\urllib3\util\connection.py", line 85, in create_connection
    raise err
  File "C:\Users\Andrew the master\Documents\GitHub\TraidingAlgorithm\venv\Lib\site-packages\urllib3\util\connection.py", line 73, in create_connection
    sock.connect(sa)
ConnectionRefusedError: [WinError 10061] No connection could be made because the target machine actively refused it

The above exception was the direct cause of the following exception:

Traceback (most recent call last):
  File "C:\Users\Andrew the master\Documents\GitHub\TraidingAlgorithm\venv\Lib\site-packages\urllib3\connectionpool.py", line 790, in urlopen
    response = self._make_request(
               ^^^^^^^^^^^^^^^^^^^
  File "C:\Users\Andrew the master\Documents\GitHub\TraidingAlgorithm\venv\Lib\site-packages\urllib3\connectionpool.py", line 496, in _make_request
    conn.request(
  File "C:\Users\Andrew the master\Documents\GitHub\TraidingAlgorithm\venv\Lib\site-packages\urllib3\connection.py", line 395, in request
    self.endheaders()
  File "C:\Users\Andrew the master\AppData\Local\Programs\Python\Python311\Lib\http\client.py", line 1278, in endheaders
    self._send_output(message_body, encode_chunked=encode_chunked)
  File "C:\Users\Andrew the master\AppData\Local\Programs\Python\Python311\Lib\http\client.py", line 1038, in _send_output
    self.send(msg)
  File "C:\Users\Andrew the master\AppData\Local\Programs\Python\Python311\Lib\http\client.py", line 976, in send
    self.connect()
  File "C:\Users\Andrew the master\Documents\GitHub\TraidingAlgorithm\venv\Lib\site-packages\urllib3\connection.py", line 243, in connect
    self.sock = self._new_conn()
                ^^^^^^^^^^^^^^^^
  File "C:\Users\Andrew the master\Documents\GitHub\TraidingAlgorithm\venv\Lib\site-packages\urllib3\connection.py", line 218, in _new_conn
    raise NewConnectionError(
urllib3.exceptions.NewConnectionError: <urllib3.connection.HTTPConnection object at 0x0000021AFFB20CD0>: Failed to establish a new connection: [WinError 10061] No connection could be made because the target machine actively refused it

The above exception was the direct cause of the following exception:

Traceback (most recent call last):
  File "C:\Users\Andrew the master\Documents\GitHub\TraidingAlgorithm\venv\Lib\site-packages\requests\adapters.py", line 486, in send
    resp = conn.urlopen(
           ^^^^^^^^^^^^^
  File "C:\Users\Andrew the master\Documents\GitHub\TraidingAlgorithm\venv\Lib\site-packages\urllib3\connectionpool.py", line 844, in urlopen
    retries = retries.increment(
              ^^^^^^^^^^^^^^^^^^
  File "C:\Users\Andrew the master\Documents\GitHub\TraidingAlgorithm\venv\Lib\site-packages\urllib3\util\retry.py", line 515, in increment
    raise MaxRetryError(_pool, url, reason) from reason  # type: ignore[arg-type]
    ^^^^^^^^^^^^^^^^^^^^^^^^^^^^^^^^^^^^^^^^^^^^^^^^^^^
urllib3.exceptions.MaxRetryError: HTTPConnectionPool(host='127.0.0.1', port=5000): Max retries exceeded with url: /api/v1/engulfing-pattern (Caused by NewConnectionError('<urllib3.connection.HTTPConnection object at 0x0000021AFFB20CD0>: Failed to establish a new connection: [WinError 10061] No connection could be made because the target machine actively refused it'))

During handling of the above exception, another exception occurred:

Traceback (most recent call last):
  File "c:\Users\Andrew the master\Documents\GitHub\TraidingAlgorithm\main.py", line 906, in BTCUSDT_60min
    getAlert(dft2, '60min', 'Close', 28, 'HeikinAshi', symb)
  File "c:\Users\Andrew the master\Documents\GitHub\TraidingAlgorithm\main.py", line 278, in getAlert
    requests.post(url=url, data=data, headers=headers)
  File "C:\Users\Andrew the master\Documents\GitHub\TraidingAlgorithm\venv\Lib\site-packages\requests\api.py", line 115, in post
    return request("post", url, data=data, json=json, **kwargs)
           ^^^^^^^^^^^^^^^^^^^^^^^^^^^^^^^^^^^^^^^^^^^^^^^^^^^^
  File "C:\Users\Andrew the master\Documents\GitHub\TraidingAlgorithm\venv\Lib\site-packages\requests\api.py", line 59, in request
    return session.request(method=method, url=url, **kwargs)
           ^^^^^^^^^^^^^^^^^^^^^^^^^^^^^^^^^^^^^^^^^^^^^^^^^
  File "C:\Users\Andrew the master\Documents\GitHub\TraidingAlgorithm\venv\Lib\site-packages\requests\sessions.py", line 589, in request
    resp = self.send(prep, **send_kwargs)
           ^^^^^^^^^^^^^^^^^^^^^^^^^^^^^^
  File "C:\Users\Andrew the master\Documents\GitHub\TraidingAlgorithm\venv\Lib\site-packages\requests\sessions.py", line 703, in send
    r = adapter.send(request, **kwargs)
        ^^^^^^^^^^^^^^^^^^^^^^^^^^^^^^^
  File "C:\Users\Andrew the master\Documents\GitHub\TraidingAlgorithm\venv\Lib\site-packages\requests\adapters.py", line 519, in send
    raise ConnectionError(e, request=request)
requests.exceptions.ConnectionError: HTTPConnectionPool(host='127.0.0.1', port=5000): Max retries exceeded with url: /api/v1/engulfing-pattern (Caused by NewConnectionError('<urllib3.connection.HTTPConnection object at 0x0000021AFFB20CD0>: Failed to establish a new connection: [WinError 10061] No connection could be made because the target machine actively refused it'))
2024-05-04 15:38:08,992 DEBUG Starting new HTTPS connection (1): api.bybit.com:443
2024-05-04 15:38:09,961 DEBUG https://api.bybit.com:443 "GET /v5/market/kline?category=spot&symbol=XRPUSDT&interval=60&limit=300 HTTP/1.1" 200 25152
2024-05-04 15:38:09,970 DEBUG Starting new HTTPS connection (1): api.bybit.com:443
2024-05-04 15:38:10,466 DEBUG https://api.bybit.com:443 "GET /v5/market/kline?category=spot&symbol=XRPUSDT&interval=60&limit=300 HTTP/1.1" 200 25152
2024-05-04 15:38:10,740 DEBUG Starting new HTTP connection (1): 127.0.0.1:5000
2024-05-04 15:38:12,781 ERROR 60min tf   
Traceback (most recent call last):
  File "C:\Users\Andrew the master\Documents\GitHub\TraidingAlgorithm\venv\Lib\site-packages\urllib3\connection.py", line 203, in _new_conn
    sock = connection.create_connection(
           ^^^^^^^^^^^^^^^^^^^^^^^^^^^^^
  File "C:\Users\Andrew the master\Documents\GitHub\TraidingAlgorithm\venv\Lib\site-packages\urllib3\util\connection.py", line 85, in create_connection
    raise err
  File "C:\Users\Andrew the master\Documents\GitHub\TraidingAlgorithm\venv\Lib\site-packages\urllib3\util\connection.py", line 73, in create_connection
    sock.connect(sa)
ConnectionRefusedError: [WinError 10061] No connection could be made because the target machine actively refused it

The above exception was the direct cause of the following exception:

Traceback (most recent call last):
  File "C:\Users\Andrew the master\Documents\GitHub\TraidingAlgorithm\venv\Lib\site-packages\urllib3\connectionpool.py", line 790, in urlopen
    response = self._make_request(
               ^^^^^^^^^^^^^^^^^^^
  File "C:\Users\Andrew the master\Documents\GitHub\TraidingAlgorithm\venv\Lib\site-packages\urllib3\connectionpool.py", line 496, in _make_request
    conn.request(
  File "C:\Users\Andrew the master\Documents\GitHub\TraidingAlgorithm\venv\Lib\site-packages\urllib3\connection.py", line 395, in request
    self.endheaders()
  File "C:\Users\Andrew the master\AppData\Local\Programs\Python\Python311\Lib\http\client.py", line 1278, in endheaders
    self._send_output(message_body, encode_chunked=encode_chunked)
  File "C:\Users\Andrew the master\AppData\Local\Programs\Python\Python311\Lib\http\client.py", line 1038, in _send_output
    self.send(msg)
  File "C:\Users\Andrew the master\AppData\Local\Programs\Python\Python311\Lib\http\client.py", line 976, in send
    self.connect()
  File "C:\Users\Andrew the master\Documents\GitHub\TraidingAlgorithm\venv\Lib\site-packages\urllib3\connection.py", line 243, in connect
    self.sock = self._new_conn()
                ^^^^^^^^^^^^^^^^
  File "C:\Users\Andrew the master\Documents\GitHub\TraidingAlgorithm\venv\Lib\site-packages\urllib3\connection.py", line 218, in _new_conn
    raise NewConnectionError(
urllib3.exceptions.NewConnectionError: <urllib3.connection.HTTPConnection object at 0x0000021AFFA493D0>: Failed to establish a new connection: [WinError 10061] No connection could be made because the target machine actively refused it

The above exception was the direct cause of the following exception:

Traceback (most recent call last):
  File "C:\Users\Andrew the master\Documents\GitHub\TraidingAlgorithm\venv\Lib\site-packages\requests\adapters.py", line 486, in send
    resp = conn.urlopen(
           ^^^^^^^^^^^^^
  File "C:\Users\Andrew the master\Documents\GitHub\TraidingAlgorithm\venv\Lib\site-packages\urllib3\connectionpool.py", line 844, in urlopen
    retries = retries.increment(
              ^^^^^^^^^^^^^^^^^^
  File "C:\Users\Andrew the master\Documents\GitHub\TraidingAlgorithm\venv\Lib\site-packages\urllib3\util\retry.py", line 515, in increment
    raise MaxRetryError(_pool, url, reason) from reason  # type: ignore[arg-type]
    ^^^^^^^^^^^^^^^^^^^^^^^^^^^^^^^^^^^^^^^^^^^^^^^^^^^
urllib3.exceptions.MaxRetryError: HTTPConnectionPool(host='127.0.0.1', port=5000): Max retries exceeded with url: /api/v1/engulfing-pattern (Caused by NewConnectionError('<urllib3.connection.HTTPConnection object at 0x0000021AFFA493D0>: Failed to establish a new connection: [WinError 10061] No connection could be made because the target machine actively refused it'))

During handling of the above exception, another exception occurred:

Traceback (most recent call last):
  File "c:\Users\Andrew the master\Documents\GitHub\TraidingAlgorithm\main.py", line 906, in BTCUSDT_60min
    getAlert(dft2, '60min', 'Close', 28, 'HeikinAshi', symb)
  File "c:\Users\Andrew the master\Documents\GitHub\TraidingAlgorithm\main.py", line 278, in getAlert
    requests.post(url=url, data=data, headers=headers)
  File "C:\Users\Andrew the master\Documents\GitHub\TraidingAlgorithm\venv\Lib\site-packages\requests\api.py", line 115, in post
    return request("post", url, data=data, json=json, **kwargs)
           ^^^^^^^^^^^^^^^^^^^^^^^^^^^^^^^^^^^^^^^^^^^^^^^^^^^^
  File "C:\Users\Andrew the master\Documents\GitHub\TraidingAlgorithm\venv\Lib\site-packages\requests\api.py", line 59, in request
    return session.request(method=method, url=url, **kwargs)
           ^^^^^^^^^^^^^^^^^^^^^^^^^^^^^^^^^^^^^^^^^^^^^^^^^
  File "C:\Users\Andrew the master\Documents\GitHub\TraidingAlgorithm\venv\Lib\site-packages\requests\sessions.py", line 589, in request
    resp = self.send(prep, **send_kwargs)
           ^^^^^^^^^^^^^^^^^^^^^^^^^^^^^^
  File "C:\Users\Andrew the master\Documents\GitHub\TraidingAlgorithm\venv\Lib\site-packages\requests\sessions.py", line 703, in send
    r = adapter.send(request, **kwargs)
        ^^^^^^^^^^^^^^^^^^^^^^^^^^^^^^^
  File "C:\Users\Andrew the master\Documents\GitHub\TraidingAlgorithm\venv\Lib\site-packages\requests\adapters.py", line 519, in send
    raise ConnectionError(e, request=request)
requests.exceptions.ConnectionError: HTTPConnectionPool(host='127.0.0.1', port=5000): Max retries exceeded with url: /api/v1/engulfing-pattern (Caused by NewConnectionError('<urllib3.connection.HTTPConnection object at 0x0000021AFFA493D0>: Failed to establish a new connection: [WinError 10061] No connection could be made because the target machine actively refused it'))
2024-05-04 15:38:12,786 DEBUG Starting new HTTPS connection (1): api.bybit.com:443
2024-05-04 15:38:13,684 DEBUG https://api.bybit.com:443 "GET /v5/market/kline?category=spot&symbol=CTCUSDT&interval=60&limit=300 HTTP/1.1" 200 26676
2024-05-04 15:38:13,691 DEBUG Starting new HTTPS connection (1): api.bybit.com:443
2024-05-04 15:38:14,210 DEBUG https://api.bybit.com:443 "GET /v5/market/kline?category=spot&symbol=CTCUSDT&interval=60&limit=300 HTTP/1.1" 200 26676
2024-05-04 15:38:14,476 DEBUG Starting new HTTP connection (1): 127.0.0.1:5000
2024-05-04 15:38:16,525 ERROR 60min tf   
Traceback (most recent call last):
  File "C:\Users\Andrew the master\Documents\GitHub\TraidingAlgorithm\venv\Lib\site-packages\urllib3\connection.py", line 203, in _new_conn
    sock = connection.create_connection(
           ^^^^^^^^^^^^^^^^^^^^^^^^^^^^^
  File "C:\Users\Andrew the master\Documents\GitHub\TraidingAlgorithm\venv\Lib\site-packages\urllib3\util\connection.py", line 85, in create_connection
    raise err
  File "C:\Users\Andrew the master\Documents\GitHub\TraidingAlgorithm\venv\Lib\site-packages\urllib3\util\connection.py", line 73, in create_connection
    sock.connect(sa)
ConnectionRefusedError: [WinError 10061] No connection could be made because the target machine actively refused it

The above exception was the direct cause of the following exception:

Traceback (most recent call last):
  File "C:\Users\Andrew the master\Documents\GitHub\TraidingAlgorithm\venv\Lib\site-packages\urllib3\connectionpool.py", line 790, in urlopen
    response = self._make_request(
               ^^^^^^^^^^^^^^^^^^^
  File "C:\Users\Andrew the master\Documents\GitHub\TraidingAlgorithm\venv\Lib\site-packages\urllib3\connectionpool.py", line 496, in _make_request
    conn.request(
  File "C:\Users\Andrew the master\Documents\GitHub\TraidingAlgorithm\venv\Lib\site-packages\urllib3\connection.py", line 395, in request
    self.endheaders()
  File "C:\Users\Andrew the master\AppData\Local\Programs\Python\Python311\Lib\http\client.py", line 1278, in endheaders
    self._send_output(message_body, encode_chunked=encode_chunked)
  File "C:\Users\Andrew the master\AppData\Local\Programs\Python\Python311\Lib\http\client.py", line 1038, in _send_output
    self.send(msg)
  File "C:\Users\Andrew the master\AppData\Local\Programs\Python\Python311\Lib\http\client.py", line 976, in send
    self.connect()
  File "C:\Users\Andrew the master\Documents\GitHub\TraidingAlgorithm\venv\Lib\site-packages\urllib3\connection.py", line 243, in connect
    self.sock = self._new_conn()
                ^^^^^^^^^^^^^^^^
  File "C:\Users\Andrew the master\Documents\GitHub\TraidingAlgorithm\venv\Lib\site-packages\urllib3\connection.py", line 218, in _new_conn
    raise NewConnectionError(
urllib3.exceptions.NewConnectionError: <urllib3.connection.HTTPConnection object at 0x0000021AFF9DD9D0>: Failed to establish a new connection: [WinError 10061] No connection could be made because the target machine actively refused it

The above exception was the direct cause of the following exception:

Traceback (most recent call last):
  File "C:\Users\Andrew the master\Documents\GitHub\TraidingAlgorithm\venv\Lib\site-packages\requests\adapters.py", line 486, in send
    resp = conn.urlopen(
           ^^^^^^^^^^^^^
  File "C:\Users\Andrew the master\Documents\GitHub\TraidingAlgorithm\venv\Lib\site-packages\urllib3\connectionpool.py", line 844, in urlopen
    retries = retries.increment(
              ^^^^^^^^^^^^^^^^^^
  File "C:\Users\Andrew the master\Documents\GitHub\TraidingAlgorithm\venv\Lib\site-packages\urllib3\util\retry.py", line 515, in increment
    raise MaxRetryError(_pool, url, reason) from reason  # type: ignore[arg-type]
    ^^^^^^^^^^^^^^^^^^^^^^^^^^^^^^^^^^^^^^^^^^^^^^^^^^^
urllib3.exceptions.MaxRetryError: HTTPConnectionPool(host='127.0.0.1', port=5000): Max retries exceeded with url: /api/v1/engulfing-pattern (Caused by NewConnectionError('<urllib3.connection.HTTPConnection object at 0x0000021AFF9DD9D0>: Failed to establish a new connection: [WinError 10061] No connection could be made because the target machine actively refused it'))

During handling of the above exception, another exception occurred:

Traceback (most recent call last):
  File "c:\Users\Andrew the master\Documents\GitHub\TraidingAlgorithm\main.py", line 906, in BTCUSDT_60min
    getAlert(dft2, '60min', 'Close', 28, 'HeikinAshi', symb)
  File "c:\Users\Andrew the master\Documents\GitHub\TraidingAlgorithm\main.py", line 278, in getAlert
    requests.post(url=url, data=data, headers=headers)
  File "C:\Users\Andrew the master\Documents\GitHub\TraidingAlgorithm\venv\Lib\site-packages\requests\api.py", line 115, in post
    return request("post", url, data=data, json=json, **kwargs)
           ^^^^^^^^^^^^^^^^^^^^^^^^^^^^^^^^^^^^^^^^^^^^^^^^^^^^
  File "C:\Users\Andrew the master\Documents\GitHub\TraidingAlgorithm\venv\Lib\site-packages\requests\api.py", line 59, in request
    return session.request(method=method, url=url, **kwargs)
           ^^^^^^^^^^^^^^^^^^^^^^^^^^^^^^^^^^^^^^^^^^^^^^^^^
  File "C:\Users\Andrew the master\Documents\GitHub\TraidingAlgorithm\venv\Lib\site-packages\requests\sessions.py", line 589, in request
    resp = self.send(prep, **send_kwargs)
           ^^^^^^^^^^^^^^^^^^^^^^^^^^^^^^
  File "C:\Users\Andrew the master\Documents\GitHub\TraidingAlgorithm\venv\Lib\site-packages\requests\sessions.py", line 703, in send
    r = adapter.send(request, **kwargs)
        ^^^^^^^^^^^^^^^^^^^^^^^^^^^^^^^
  File "C:\Users\Andrew the master\Documents\GitHub\TraidingAlgorithm\venv\Lib\site-packages\requests\adapters.py", line 519, in send
    raise ConnectionError(e, request=request)
requests.exceptions.ConnectionError: HTTPConnectionPool(host='127.0.0.1', port=5000): Max retries exceeded with url: /api/v1/engulfing-pattern (Caused by NewConnectionError('<urllib3.connection.HTTPConnection object at 0x0000021AFF9DD9D0>: Failed to establish a new connection: [WinError 10061] No connection could be made because the target machine actively refused it'))
2024-05-04 15:38:16,530 DEBUG Starting new HTTPS connection (1): api.bybit.com:443
2024-05-04 15:38:17,056 DEBUG https://api.bybit.com:443 "GET /v5/market/kline?category=spot&symbol=PLANETUSDT&interval=60&limit=300 HTTP/1.1" 200 31368
2024-05-04 15:38:17,065 DEBUG Starting new HTTPS connection (1): api.bybit.com:443
2024-05-04 15:38:17,758 DEBUG https://api.bybit.com:443 "GET /v5/market/kline?category=spot&symbol=PLANETUSDT&interval=60&limit=300 HTTP/1.1" 200 31368
2024-05-04 15:38:18,160 DEBUG Starting new HTTP connection (1): 127.0.0.1:5000
2024-05-04 15:38:20,206 ERROR 60min tf   
Traceback (most recent call last):
  File "C:\Users\Andrew the master\Documents\GitHub\TraidingAlgorithm\venv\Lib\site-packages\urllib3\connection.py", line 203, in _new_conn
    sock = connection.create_connection(
           ^^^^^^^^^^^^^^^^^^^^^^^^^^^^^
  File "C:\Users\Andrew the master\Documents\GitHub\TraidingAlgorithm\venv\Lib\site-packages\urllib3\util\connection.py", line 85, in create_connection
    raise err
  File "C:\Users\Andrew the master\Documents\GitHub\TraidingAlgorithm\venv\Lib\site-packages\urllib3\util\connection.py", line 73, in create_connection
    sock.connect(sa)
ConnectionRefusedError: [WinError 10061] No connection could be made because the target machine actively refused it

The above exception was the direct cause of the following exception:

Traceback (most recent call last):
  File "C:\Users\Andrew the master\Documents\GitHub\TraidingAlgorithm\venv\Lib\site-packages\urllib3\connectionpool.py", line 790, in urlopen
    response = self._make_request(
               ^^^^^^^^^^^^^^^^^^^
  File "C:\Users\Andrew the master\Documents\GitHub\TraidingAlgorithm\venv\Lib\site-packages\urllib3\connectionpool.py", line 496, in _make_request
    conn.request(
  File "C:\Users\Andrew the master\Documents\GitHub\TraidingAlgorithm\venv\Lib\site-packages\urllib3\connection.py", line 395, in request
    self.endheaders()
  File "C:\Users\Andrew the master\AppData\Local\Programs\Python\Python311\Lib\http\client.py", line 1278, in endheaders
    self._send_output(message_body, encode_chunked=encode_chunked)
  File "C:\Users\Andrew the master\AppData\Local\Programs\Python\Python311\Lib\http\client.py", line 1038, in _send_output
    self.send(msg)
  File "C:\Users\Andrew the master\AppData\Local\Programs\Python\Python311\Lib\http\client.py", line 976, in send
    self.connect()
  File "C:\Users\Andrew the master\Documents\GitHub\TraidingAlgorithm\venv\Lib\site-packages\urllib3\connection.py", line 243, in connect
    self.sock = self._new_conn()
                ^^^^^^^^^^^^^^^^
  File "C:\Users\Andrew the master\Documents\GitHub\TraidingAlgorithm\venv\Lib\site-packages\urllib3\connection.py", line 218, in _new_conn
    raise NewConnectionError(
urllib3.exceptions.NewConnectionError: <urllib3.connection.HTTPConnection object at 0x0000021AFF9EF5D0>: Failed to establish a new connection: [WinError 10061] No connection could be made because the target machine actively refused it

The above exception was the direct cause of the following exception:

Traceback (most recent call last):
  File "C:\Users\Andrew the master\Documents\GitHub\TraidingAlgorithm\venv\Lib\site-packages\requests\adapters.py", line 486, in send
    resp = conn.urlopen(
           ^^^^^^^^^^^^^
  File "C:\Users\Andrew the master\Documents\GitHub\TraidingAlgorithm\venv\Lib\site-packages\urllib3\connectionpool.py", line 844, in urlopen
    retries = retries.increment(
              ^^^^^^^^^^^^^^^^^^
  File "C:\Users\Andrew the master\Documents\GitHub\TraidingAlgorithm\venv\Lib\site-packages\urllib3\util\retry.py", line 515, in increment
    raise MaxRetryError(_pool, url, reason) from reason  # type: ignore[arg-type]
    ^^^^^^^^^^^^^^^^^^^^^^^^^^^^^^^^^^^^^^^^^^^^^^^^^^^
urllib3.exceptions.MaxRetryError: HTTPConnectionPool(host='127.0.0.1', port=5000): Max retries exceeded with url: /api/v1/engulfing-pattern (Caused by NewConnectionError('<urllib3.connection.HTTPConnection object at 0x0000021AFF9EF5D0>: Failed to establish a new connection: [WinError 10061] No connection could be made because the target machine actively refused it'))

During handling of the above exception, another exception occurred:

Traceback (most recent call last):
  File "c:\Users\Andrew the master\Documents\GitHub\TraidingAlgorithm\main.py", line 906, in BTCUSDT_60min
    getAlert(dft2, '60min', 'Close', 28, 'HeikinAshi', symb)
  File "c:\Users\Andrew the master\Documents\GitHub\TraidingAlgorithm\main.py", line 278, in getAlert
    requests.post(url=url, data=data, headers=headers)
  File "C:\Users\Andrew the master\Documents\GitHub\TraidingAlgorithm\venv\Lib\site-packages\requests\api.py", line 115, in post
    return request("post", url, data=data, json=json, **kwargs)
           ^^^^^^^^^^^^^^^^^^^^^^^^^^^^^^^^^^^^^^^^^^^^^^^^^^^^
  File "C:\Users\Andrew the master\Documents\GitHub\TraidingAlgorithm\venv\Lib\site-packages\requests\api.py", line 59, in request
    return session.request(method=method, url=url, **kwargs)
           ^^^^^^^^^^^^^^^^^^^^^^^^^^^^^^^^^^^^^^^^^^^^^^^^^
  File "C:\Users\Andrew the master\Documents\GitHub\TraidingAlgorithm\venv\Lib\site-packages\requests\sessions.py", line 589, in request
    resp = self.send(prep, **send_kwargs)
           ^^^^^^^^^^^^^^^^^^^^^^^^^^^^^^
  File "C:\Users\Andrew the master\Documents\GitHub\TraidingAlgorithm\venv\Lib\site-packages\requests\sessions.py", line 703, in send
    r = adapter.send(request, **kwargs)
        ^^^^^^^^^^^^^^^^^^^^^^^^^^^^^^^
  File "C:\Users\Andrew the master\Documents\GitHub\TraidingAlgorithm\venv\Lib\site-packages\requests\adapters.py", line 519, in send
    raise ConnectionError(e, request=request)
requests.exceptions.ConnectionError: HTTPConnectionPool(host='127.0.0.1', port=5000): Max retries exceeded with url: /api/v1/engulfing-pattern (Caused by NewConnectionError('<urllib3.connection.HTTPConnection object at 0x0000021AFF9EF5D0>: Failed to establish a new connection: [WinError 10061] No connection could be made because the target machine actively refused it'))
2024-05-04 15:38:20,211 DEBUG Starting new HTTPS connection (1): api.bybit.com:443
2024-05-04 15:38:20,494 DEBUG https://api.bybit.com:443 "GET /v5/market/kline?category=spot&symbol=SOLUSDT&interval=60&limit=300 HTTP/1.1" 200 24592
2024-05-04 15:38:20,694 DEBUG Starting new HTTPS connection (1): api.bybit.com:443
2024-05-04 15:38:21,011 DEBUG https://api.bybit.com:443 "GET /v5/market/kline?category=spot&symbol=SOLUSDT&interval=60&limit=300 HTTP/1.1" 200 24593
2024-05-04 15:38:21,312 DEBUG Starting new HTTP connection (1): 127.0.0.1:5000
2024-05-04 15:38:23,351 ERROR 60min tf   
Traceback (most recent call last):
  File "C:\Users\Andrew the master\Documents\GitHub\TraidingAlgorithm\venv\Lib\site-packages\urllib3\connection.py", line 203, in _new_conn
    sock = connection.create_connection(
           ^^^^^^^^^^^^^^^^^^^^^^^^^^^^^
  File "C:\Users\Andrew the master\Documents\GitHub\TraidingAlgorithm\venv\Lib\site-packages\urllib3\util\connection.py", line 85, in create_connection
    raise err
  File "C:\Users\Andrew the master\Documents\GitHub\TraidingAlgorithm\venv\Lib\site-packages\urllib3\util\connection.py", line 73, in create_connection
    sock.connect(sa)
ConnectionRefusedError: [WinError 10061] No connection could be made because the target machine actively refused it

The above exception was the direct cause of the following exception:

Traceback (most recent call last):
  File "C:\Users\Andrew the master\Documents\GitHub\TraidingAlgorithm\venv\Lib\site-packages\urllib3\connectionpool.py", line 790, in urlopen
    response = self._make_request(
               ^^^^^^^^^^^^^^^^^^^
  File "C:\Users\Andrew the master\Documents\GitHub\TraidingAlgorithm\venv\Lib\site-packages\urllib3\connectionpool.py", line 496, in _make_request
    conn.request(
  File "C:\Users\Andrew the master\Documents\GitHub\TraidingAlgorithm\venv\Lib\site-packages\urllib3\connection.py", line 395, in request
    self.endheaders()
  File "C:\Users\Andrew the master\AppData\Local\Programs\Python\Python311\Lib\http\client.py", line 1278, in endheaders
    self._send_output(message_body, encode_chunked=encode_chunked)
  File "C:\Users\Andrew the master\AppData\Local\Programs\Python\Python311\Lib\http\client.py", line 1038, in _send_output
    self.send(msg)
  File "C:\Users\Andrew the master\AppData\Local\Programs\Python\Python311\Lib\http\client.py", line 976, in send
    self.connect()
  File "C:\Users\Andrew the master\Documents\GitHub\TraidingAlgorithm\venv\Lib\site-packages\urllib3\connection.py", line 243, in connect
    self.sock = self._new_conn()
                ^^^^^^^^^^^^^^^^
  File "C:\Users\Andrew the master\Documents\GitHub\TraidingAlgorithm\venv\Lib\site-packages\urllib3\connection.py", line 218, in _new_conn
    raise NewConnectionError(
urllib3.exceptions.NewConnectionError: <urllib3.connection.HTTPConnection object at 0x0000021AFFB259D0>: Failed to establish a new connection: [WinError 10061] No connection could be made because the target machine actively refused it

The above exception was the direct cause of the following exception:

Traceback (most recent call last):
  File "C:\Users\Andrew the master\Documents\GitHub\TraidingAlgorithm\venv\Lib\site-packages\requests\adapters.py", line 486, in send
    resp = conn.urlopen(
           ^^^^^^^^^^^^^
  File "C:\Users\Andrew the master\Documents\GitHub\TraidingAlgorithm\venv\Lib\site-packages\urllib3\connectionpool.py", line 844, in urlopen
    retries = retries.increment(
              ^^^^^^^^^^^^^^^^^^
  File "C:\Users\Andrew the master\Documents\GitHub\TraidingAlgorithm\venv\Lib\site-packages\urllib3\util\retry.py", line 515, in increment
    raise MaxRetryError(_pool, url, reason) from reason  # type: ignore[arg-type]
    ^^^^^^^^^^^^^^^^^^^^^^^^^^^^^^^^^^^^^^^^^^^^^^^^^^^
urllib3.exceptions.MaxRetryError: HTTPConnectionPool(host='127.0.0.1', port=5000): Max retries exceeded with url: /api/v1/engulfing-pattern (Caused by NewConnectionError('<urllib3.connection.HTTPConnection object at 0x0000021AFFB259D0>: Failed to establish a new connection: [WinError 10061] No connection could be made because the target machine actively refused it'))

During handling of the above exception, another exception occurred:

Traceback (most recent call last):
  File "c:\Users\Andrew the master\Documents\GitHub\TraidingAlgorithm\main.py", line 906, in BTCUSDT_60min
    getAlert(dft2, '60min', 'Close', 28, 'HeikinAshi', symb)
  File "c:\Users\Andrew the master\Documents\GitHub\TraidingAlgorithm\main.py", line 278, in getAlert
    requests.post(url=url, data=data, headers=headers)
  File "C:\Users\Andrew the master\Documents\GitHub\TraidingAlgorithm\venv\Lib\site-packages\requests\api.py", line 115, in post
    return request("post", url, data=data, json=json, **kwargs)
           ^^^^^^^^^^^^^^^^^^^^^^^^^^^^^^^^^^^^^^^^^^^^^^^^^^^^
  File "C:\Users\Andrew the master\Documents\GitHub\TraidingAlgorithm\venv\Lib\site-packages\requests\api.py", line 59, in request
    return session.request(method=method, url=url, **kwargs)
           ^^^^^^^^^^^^^^^^^^^^^^^^^^^^^^^^^^^^^^^^^^^^^^^^^
  File "C:\Users\Andrew the master\Documents\GitHub\TraidingAlgorithm\venv\Lib\site-packages\requests\sessions.py", line 589, in request
    resp = self.send(prep, **send_kwargs)
           ^^^^^^^^^^^^^^^^^^^^^^^^^^^^^^
  File "C:\Users\Andrew the master\Documents\GitHub\TraidingAlgorithm\venv\Lib\site-packages\requests\sessions.py", line 703, in send
    r = adapter.send(request, **kwargs)
        ^^^^^^^^^^^^^^^^^^^^^^^^^^^^^^^
  File "C:\Users\Andrew the master\Documents\GitHub\TraidingAlgorithm\venv\Lib\site-packages\requests\adapters.py", line 519, in send
    raise ConnectionError(e, request=request)
requests.exceptions.ConnectionError: HTTPConnectionPool(host='127.0.0.1', port=5000): Max retries exceeded with url: /api/v1/engulfing-pattern (Caused by NewConnectionError('<urllib3.connection.HTTPConnection object at 0x0000021AFFB259D0>: Failed to establish a new connection: [WinError 10061] No connection could be made because the target machine actively refused it'))
2024-05-04 15:38:23,356 DEBUG Starting new HTTPS connection (1): api.bybit.com:443
2024-05-04 15:38:24,064 DEBUG https://api.bybit.com:443 "GET /v5/market/kline?category=spot&symbol=LINKUSDT&interval=60&limit=300 HTTP/1.1" 200 25993
2024-05-04 15:38:24,278 DEBUG Starting new HTTPS connection (1): api.bybit.com:443
2024-05-04 15:38:24,578 DEBUG https://api.bybit.com:443 "GET /v5/market/kline?category=spot&symbol=LINKUSDT&interval=60&limit=300 HTTP/1.1" 200 25993
2024-05-04 15:38:24,887 DEBUG Starting new HTTP connection (1): 127.0.0.1:5000
2024-05-04 15:38:26,925 ERROR 60min tf   
Traceback (most recent call last):
  File "C:\Users\Andrew the master\Documents\GitHub\TraidingAlgorithm\venv\Lib\site-packages\urllib3\connection.py", line 203, in _new_conn
    sock = connection.create_connection(
           ^^^^^^^^^^^^^^^^^^^^^^^^^^^^^
  File "C:\Users\Andrew the master\Documents\GitHub\TraidingAlgorithm\venv\Lib\site-packages\urllib3\util\connection.py", line 85, in create_connection
    raise err
  File "C:\Users\Andrew the master\Documents\GitHub\TraidingAlgorithm\venv\Lib\site-packages\urllib3\util\connection.py", line 73, in create_connection
    sock.connect(sa)
ConnectionRefusedError: [WinError 10061] No connection could be made because the target machine actively refused it

The above exception was the direct cause of the following exception:

Traceback (most recent call last):
  File "C:\Users\Andrew the master\Documents\GitHub\TraidingAlgorithm\venv\Lib\site-packages\urllib3\connectionpool.py", line 790, in urlopen
    response = self._make_request(
               ^^^^^^^^^^^^^^^^^^^
  File "C:\Users\Andrew the master\Documents\GitHub\TraidingAlgorithm\venv\Lib\site-packages\urllib3\connectionpool.py", line 496, in _make_request
    conn.request(
  File "C:\Users\Andrew the master\Documents\GitHub\TraidingAlgorithm\venv\Lib\site-packages\urllib3\connection.py", line 395, in request
    self.endheaders()
  File "C:\Users\Andrew the master\AppData\Local\Programs\Python\Python311\Lib\http\client.py", line 1278, in endheaders
    self._send_output(message_body, encode_chunked=encode_chunked)
  File "C:\Users\Andrew the master\AppData\Local\Programs\Python\Python311\Lib\http\client.py", line 1038, in _send_output
    self.send(msg)
  File "C:\Users\Andrew the master\AppData\Local\Programs\Python\Python311\Lib\http\client.py", line 976, in send
    self.connect()
  File "C:\Users\Andrew the master\Documents\GitHub\TraidingAlgorithm\venv\Lib\site-packages\urllib3\connection.py", line 243, in connect
    self.sock = self._new_conn()
                ^^^^^^^^^^^^^^^^
  File "C:\Users\Andrew the master\Documents\GitHub\TraidingAlgorithm\venv\Lib\site-packages\urllib3\connection.py", line 218, in _new_conn
    raise NewConnectionError(
urllib3.exceptions.NewConnectionError: <urllib3.connection.HTTPConnection object at 0x0000021AFFA32B90>: Failed to establish a new connection: [WinError 10061] No connection could be made because the target machine actively refused it

The above exception was the direct cause of the following exception:

Traceback (most recent call last):
  File "C:\Users\Andrew the master\Documents\GitHub\TraidingAlgorithm\venv\Lib\site-packages\requests\adapters.py", line 486, in send
    resp = conn.urlopen(
           ^^^^^^^^^^^^^
  File "C:\Users\Andrew the master\Documents\GitHub\TraidingAlgorithm\venv\Lib\site-packages\urllib3\connectionpool.py", line 844, in urlopen
    retries = retries.increment(
              ^^^^^^^^^^^^^^^^^^
  File "C:\Users\Andrew the master\Documents\GitHub\TraidingAlgorithm\venv\Lib\site-packages\urllib3\util\retry.py", line 515, in increment
    raise MaxRetryError(_pool, url, reason) from reason  # type: ignore[arg-type]
    ^^^^^^^^^^^^^^^^^^^^^^^^^^^^^^^^^^^^^^^^^^^^^^^^^^^
urllib3.exceptions.MaxRetryError: HTTPConnectionPool(host='127.0.0.1', port=5000): Max retries exceeded with url: /api/v1/engulfing-pattern (Caused by NewConnectionError('<urllib3.connection.HTTPConnection object at 0x0000021AFFA32B90>: Failed to establish a new connection: [WinError 10061] No connection could be made because the target machine actively refused it'))

During handling of the above exception, another exception occurred:

Traceback (most recent call last):
  File "c:\Users\Andrew the master\Documents\GitHub\TraidingAlgorithm\main.py", line 906, in BTCUSDT_60min
    getAlert(dft2, '60min', 'Close', 28, 'HeikinAshi', symb)
  File "c:\Users\Andrew the master\Documents\GitHub\TraidingAlgorithm\main.py", line 278, in getAlert
    requests.post(url=url, data=data, headers=headers)
  File "C:\Users\Andrew the master\Documents\GitHub\TraidingAlgorithm\venv\Lib\site-packages\requests\api.py", line 115, in post
    return request("post", url, data=data, json=json, **kwargs)
           ^^^^^^^^^^^^^^^^^^^^^^^^^^^^^^^^^^^^^^^^^^^^^^^^^^^^
  File "C:\Users\Andrew the master\Documents\GitHub\TraidingAlgorithm\venv\Lib\site-packages\requests\api.py", line 59, in request
    return session.request(method=method, url=url, **kwargs)
           ^^^^^^^^^^^^^^^^^^^^^^^^^^^^^^^^^^^^^^^^^^^^^^^^^
  File "C:\Users\Andrew the master\Documents\GitHub\TraidingAlgorithm\venv\Lib\site-packages\requests\sessions.py", line 589, in request
    resp = self.send(prep, **send_kwargs)
           ^^^^^^^^^^^^^^^^^^^^^^^^^^^^^^
  File "C:\Users\Andrew the master\Documents\GitHub\TraidingAlgorithm\venv\Lib\site-packages\requests\sessions.py", line 703, in send
    r = adapter.send(request, **kwargs)
        ^^^^^^^^^^^^^^^^^^^^^^^^^^^^^^^
  File "C:\Users\Andrew the master\Documents\GitHub\TraidingAlgorithm\venv\Lib\site-packages\requests\adapters.py", line 519, in send
    raise ConnectionError(e, request=request)
requests.exceptions.ConnectionError: HTTPConnectionPool(host='127.0.0.1', port=5000): Max retries exceeded with url: /api/v1/engulfing-pattern (Caused by NewConnectionError('<urllib3.connection.HTTPConnection object at 0x0000021AFFA32B90>: Failed to establish a new connection: [WinError 10061] No connection could be made because the target machine actively refused it'))
2024-05-04 15:38:26,929 DEBUG Starting new HTTPS connection (1): api.bybit.com:443
2024-05-04 15:38:27,533 DEBUG https://api.bybit.com:443 "GET /v5/market/kline?category=spot&symbol=FBUSDT&interval=60&limit=300 HTTP/1.1" 200 21732
2024-05-04 15:38:27,542 DEBUG Starting new HTTPS connection (1): api.bybit.com:443
2024-05-04 15:38:28,223 DEBUG https://api.bybit.com:443 "GET /v5/market/kline?category=spot&symbol=FBUSDT&interval=60&limit=300 HTTP/1.1" 200 21732
2024-05-04 15:38:28,665 DEBUG Starting new HTTP connection (1): 127.0.0.1:5000
2024-05-04 15:38:30,710 ERROR 60min tf   
Traceback (most recent call last):
  File "C:\Users\Andrew the master\Documents\GitHub\TraidingAlgorithm\venv\Lib\site-packages\urllib3\connection.py", line 203, in _new_conn
    sock = connection.create_connection(
           ^^^^^^^^^^^^^^^^^^^^^^^^^^^^^
  File "C:\Users\Andrew the master\Documents\GitHub\TraidingAlgorithm\venv\Lib\site-packages\urllib3\util\connection.py", line 85, in create_connection
    raise err
  File "C:\Users\Andrew the master\Documents\GitHub\TraidingAlgorithm\venv\Lib\site-packages\urllib3\util\connection.py", line 73, in create_connection
    sock.connect(sa)
ConnectionRefusedError: [WinError 10061] No connection could be made because the target machine actively refused it

The above exception was the direct cause of the following exception:

Traceback (most recent call last):
  File "C:\Users\Andrew the master\Documents\GitHub\TraidingAlgorithm\venv\Lib\site-packages\urllib3\connectionpool.py", line 790, in urlopen
    response = self._make_request(
               ^^^^^^^^^^^^^^^^^^^
  File "C:\Users\Andrew the master\Documents\GitHub\TraidingAlgorithm\venv\Lib\site-packages\urllib3\connectionpool.py", line 496, in _make_request
    conn.request(
  File "C:\Users\Andrew the master\Documents\GitHub\TraidingAlgorithm\venv\Lib\site-packages\urllib3\connection.py", line 395, in request
    self.endheaders()
  File "C:\Users\Andrew the master\AppData\Local\Programs\Python\Python311\Lib\http\client.py", line 1278, in endheaders
    self._send_output(message_body, encode_chunked=encode_chunked)
  File "C:\Users\Andrew the master\AppData\Local\Programs\Python\Python311\Lib\http\client.py", line 1038, in _send_output
    self.send(msg)
  File "C:\Users\Andrew the master\AppData\Local\Programs\Python\Python311\Lib\http\client.py", line 976, in send
    self.connect()
  File "C:\Users\Andrew the master\Documents\GitHub\TraidingAlgorithm\venv\Lib\site-packages\urllib3\connection.py", line 243, in connect
    self.sock = self._new_conn()
                ^^^^^^^^^^^^^^^^
  File "C:\Users\Andrew the master\Documents\GitHub\TraidingAlgorithm\venv\Lib\site-packages\urllib3\connection.py", line 218, in _new_conn
    raise NewConnectionError(
urllib3.exceptions.NewConnectionError: <urllib3.connection.HTTPConnection object at 0x0000021AFFB21BD0>: Failed to establish a new connection: [WinError 10061] No connection could be made because the target machine actively refused it

The above exception was the direct cause of the following exception:

Traceback (most recent call last):
  File "C:\Users\Andrew the master\Documents\GitHub\TraidingAlgorithm\venv\Lib\site-packages\requests\adapters.py", line 486, in send
    resp = conn.urlopen(
           ^^^^^^^^^^^^^
  File "C:\Users\Andrew the master\Documents\GitHub\TraidingAlgorithm\venv\Lib\site-packages\urllib3\connectionpool.py", line 844, in urlopen
    retries = retries.increment(
              ^^^^^^^^^^^^^^^^^^
  File "C:\Users\Andrew the master\Documents\GitHub\TraidingAlgorithm\venv\Lib\site-packages\urllib3\util\retry.py", line 515, in increment
    raise MaxRetryError(_pool, url, reason) from reason  # type: ignore[arg-type]
    ^^^^^^^^^^^^^^^^^^^^^^^^^^^^^^^^^^^^^^^^^^^^^^^^^^^
urllib3.exceptions.MaxRetryError: HTTPConnectionPool(host='127.0.0.1', port=5000): Max retries exceeded with url: /api/v1/engulfing-pattern (Caused by NewConnectionError('<urllib3.connection.HTTPConnection object at 0x0000021AFFB21BD0>: Failed to establish a new connection: [WinError 10061] No connection could be made because the target machine actively refused it'))

During handling of the above exception, another exception occurred:

Traceback (most recent call last):
  File "c:\Users\Andrew the master\Documents\GitHub\TraidingAlgorithm\main.py", line 906, in BTCUSDT_60min
    getAlert(dft2, '60min', 'Close', 28, 'HeikinAshi', symb)
  File "c:\Users\Andrew the master\Documents\GitHub\TraidingAlgorithm\main.py", line 278, in getAlert
    requests.post(url=url, data=data, headers=headers)
  File "C:\Users\Andrew the master\Documents\GitHub\TraidingAlgorithm\venv\Lib\site-packages\requests\api.py", line 115, in post
    return request("post", url, data=data, json=json, **kwargs)
           ^^^^^^^^^^^^^^^^^^^^^^^^^^^^^^^^^^^^^^^^^^^^^^^^^^^^
  File "C:\Users\Andrew the master\Documents\GitHub\TraidingAlgorithm\venv\Lib\site-packages\requests\api.py", line 59, in request
    return session.request(method=method, url=url, **kwargs)
           ^^^^^^^^^^^^^^^^^^^^^^^^^^^^^^^^^^^^^^^^^^^^^^^^^
  File "C:\Users\Andrew the master\Documents\GitHub\TraidingAlgorithm\venv\Lib\site-packages\requests\sessions.py", line 589, in request
    resp = self.send(prep, **send_kwargs)
           ^^^^^^^^^^^^^^^^^^^^^^^^^^^^^^
  File "C:\Users\Andrew the master\Documents\GitHub\TraidingAlgorithm\venv\Lib\site-packages\requests\sessions.py", line 703, in send
    r = adapter.send(request, **kwargs)
        ^^^^^^^^^^^^^^^^^^^^^^^^^^^^^^^
  File "C:\Users\Andrew the master\Documents\GitHub\TraidingAlgorithm\venv\Lib\site-packages\requests\adapters.py", line 519, in send
    raise ConnectionError(e, request=request)
requests.exceptions.ConnectionError: HTTPConnectionPool(host='127.0.0.1', port=5000): Max retries exceeded with url: /api/v1/engulfing-pattern (Caused by NewConnectionError('<urllib3.connection.HTTPConnection object at 0x0000021AFFB21BD0>: Failed to establish a new connection: [WinError 10061] No connection could be made because the target machine actively refused it'))
2024-05-04 15:38:30,715 DEBUG Starting new HTTPS connection (1): api.bybit.com:443
2024-05-04 15:38:31,413 DEBUG https://api.bybit.com:443 "GET /v5/market/kline?category=spot&symbol=APTUSDT&interval=60&limit=300 HTTP/1.1" 200 24374
2024-05-04 15:38:31,625 DEBUG Starting new HTTPS connection (1): api.bybit.com:443
2024-05-04 15:38:32,139 DEBUG https://api.bybit.com:443 "GET /v5/market/kline?category=spot&symbol=APTUSDT&interval=60&limit=300 HTTP/1.1" 200 None
2024-05-04 15:38:32,420 DEBUG Starting new HTTP connection (1): 127.0.0.1:5000
2024-05-04 15:38:34,457 ERROR 60min tf   
Traceback (most recent call last):
  File "C:\Users\Andrew the master\Documents\GitHub\TraidingAlgorithm\venv\Lib\site-packages\urllib3\connection.py", line 203, in _new_conn
    sock = connection.create_connection(
           ^^^^^^^^^^^^^^^^^^^^^^^^^^^^^
  File "C:\Users\Andrew the master\Documents\GitHub\TraidingAlgorithm\venv\Lib\site-packages\urllib3\util\connection.py", line 85, in create_connection
    raise err
  File "C:\Users\Andrew the master\Documents\GitHub\TraidingAlgorithm\venv\Lib\site-packages\urllib3\util\connection.py", line 73, in create_connection
    sock.connect(sa)
ConnectionRefusedError: [WinError 10061] No connection could be made because the target machine actively refused it

The above exception was the direct cause of the following exception:

Traceback (most recent call last):
  File "C:\Users\Andrew the master\Documents\GitHub\TraidingAlgorithm\venv\Lib\site-packages\urllib3\connectionpool.py", line 790, in urlopen
    response = self._make_request(
               ^^^^^^^^^^^^^^^^^^^
  File "C:\Users\Andrew the master\Documents\GitHub\TraidingAlgorithm\venv\Lib\site-packages\urllib3\connectionpool.py", line 496, in _make_request
    conn.request(
  File "C:\Users\Andrew the master\Documents\GitHub\TraidingAlgorithm\venv\Lib\site-packages\urllib3\connection.py", line 395, in request
    self.endheaders()
  File "C:\Users\Andrew the master\AppData\Local\Programs\Python\Python311\Lib\http\client.py", line 1278, in endheaders
    self._send_output(message_body, encode_chunked=encode_chunked)
  File "C:\Users\Andrew the master\AppData\Local\Programs\Python\Python311\Lib\http\client.py", line 1038, in _send_output
    self.send(msg)
  File "C:\Users\Andrew the master\AppData\Local\Programs\Python\Python311\Lib\http\client.py", line 976, in send
    self.connect()
  File "C:\Users\Andrew the master\Documents\GitHub\TraidingAlgorithm\venv\Lib\site-packages\urllib3\connection.py", line 243, in connect
    self.sock = self._new_conn()
                ^^^^^^^^^^^^^^^^
  File "C:\Users\Andrew the master\Documents\GitHub\TraidingAlgorithm\venv\Lib\site-packages\urllib3\connection.py", line 218, in _new_conn
    raise NewConnectionError(
urllib3.exceptions.NewConnectionError: <urllib3.connection.HTTPConnection object at 0x0000021AFFA4F710>: Failed to establish a new connection: [WinError 10061] No connection could be made because the target machine actively refused it

The above exception was the direct cause of the following exception:

Traceback (most recent call last):
  File "C:\Users\Andrew the master\Documents\GitHub\TraidingAlgorithm\venv\Lib\site-packages\requests\adapters.py", line 486, in send
    resp = conn.urlopen(
           ^^^^^^^^^^^^^
  File "C:\Users\Andrew the master\Documents\GitHub\TraidingAlgorithm\venv\Lib\site-packages\urllib3\connectionpool.py", line 844, in urlopen
    retries = retries.increment(
              ^^^^^^^^^^^^^^^^^^
  File "C:\Users\Andrew the master\Documents\GitHub\TraidingAlgorithm\venv\Lib\site-packages\urllib3\util\retry.py", line 515, in increment
    raise MaxRetryError(_pool, url, reason) from reason  # type: ignore[arg-type]
    ^^^^^^^^^^^^^^^^^^^^^^^^^^^^^^^^^^^^^^^^^^^^^^^^^^^
urllib3.exceptions.MaxRetryError: HTTPConnectionPool(host='127.0.0.1', port=5000): Max retries exceeded with url: /api/v1/engulfing-pattern (Caused by NewConnectionError('<urllib3.connection.HTTPConnection object at 0x0000021AFFA4F710>: Failed to establish a new connection: [WinError 10061] No connection could be made because the target machine actively refused it'))

During handling of the above exception, another exception occurred:

Traceback (most recent call last):
  File "c:\Users\Andrew the master\Documents\GitHub\TraidingAlgorithm\main.py", line 906, in BTCUSDT_60min
    getAlert(dft2, '60min', 'Close', 28, 'HeikinAshi', symb)
  File "c:\Users\Andrew the master\Documents\GitHub\TraidingAlgorithm\main.py", line 278, in getAlert
    requests.post(url=url, data=data, headers=headers)
  File "C:\Users\Andrew the master\Documents\GitHub\TraidingAlgorithm\venv\Lib\site-packages\requests\api.py", line 115, in post
    return request("post", url, data=data, json=json, **kwargs)
           ^^^^^^^^^^^^^^^^^^^^^^^^^^^^^^^^^^^^^^^^^^^^^^^^^^^^
  File "C:\Users\Andrew the master\Documents\GitHub\TraidingAlgorithm\venv\Lib\site-packages\requests\api.py", line 59, in request
    return session.request(method=method, url=url, **kwargs)
           ^^^^^^^^^^^^^^^^^^^^^^^^^^^^^^^^^^^^^^^^^^^^^^^^^
  File "C:\Users\Andrew the master\Documents\GitHub\TraidingAlgorithm\venv\Lib\site-packages\requests\sessions.py", line 589, in request
    resp = self.send(prep, **send_kwargs)
           ^^^^^^^^^^^^^^^^^^^^^^^^^^^^^^
  File "C:\Users\Andrew the master\Documents\GitHub\TraidingAlgorithm\venv\Lib\site-packages\requests\sessions.py", line 703, in send
    r = adapter.send(request, **kwargs)
        ^^^^^^^^^^^^^^^^^^^^^^^^^^^^^^^
  File "C:\Users\Andrew the master\Documents\GitHub\TraidingAlgorithm\venv\Lib\site-packages\requests\adapters.py", line 519, in send
    raise ConnectionError(e, request=request)
requests.exceptions.ConnectionError: HTTPConnectionPool(host='127.0.0.1', port=5000): Max retries exceeded with url: /api/v1/engulfing-pattern (Caused by NewConnectionError('<urllib3.connection.HTTPConnection object at 0x0000021AFFA4F710>: Failed to establish a new connection: [WinError 10061] No connection could be made because the target machine actively refused it'))
2024-05-04 15:38:34,461 DEBUG Starting new HTTPS connection (1): api.bybit.com:443
2024-05-04 15:38:34,758 DEBUG https://api.bybit.com:443 "GET /v5/market/kline?category=spot&symbol=DOGEUSDT&interval=60&limit=300 HTTP/1.1" 200 26018
2024-05-04 15:38:34,767 DEBUG Starting new HTTPS connection (1): api.bybit.com:443
2024-05-04 15:38:35,666 DEBUG https://api.bybit.com:443 "GET /v5/market/kline?category=spot&symbol=DOGEUSDT&interval=60&limit=300 HTTP/1.1" 200 26018
2024-05-04 15:38:35,980 DEBUG Starting new HTTP connection (1): 127.0.0.1:5000
2024-05-04 15:38:38,022 ERROR 60min tf   
Traceback (most recent call last):
  File "C:\Users\Andrew the master\Documents\GitHub\TraidingAlgorithm\venv\Lib\site-packages\urllib3\connection.py", line 203, in _new_conn
    sock = connection.create_connection(
           ^^^^^^^^^^^^^^^^^^^^^^^^^^^^^
  File "C:\Users\Andrew the master\Documents\GitHub\TraidingAlgorithm\venv\Lib\site-packages\urllib3\util\connection.py", line 85, in create_connection
    raise err
  File "C:\Users\Andrew the master\Documents\GitHub\TraidingAlgorithm\venv\Lib\site-packages\urllib3\util\connection.py", line 73, in create_connection
    sock.connect(sa)
ConnectionRefusedError: [WinError 10061] No connection could be made because the target machine actively refused it

The above exception was the direct cause of the following exception:

Traceback (most recent call last):
  File "C:\Users\Andrew the master\Documents\GitHub\TraidingAlgorithm\venv\Lib\site-packages\urllib3\connectionpool.py", line 790, in urlopen
    response = self._make_request(
               ^^^^^^^^^^^^^^^^^^^
  File "C:\Users\Andrew the master\Documents\GitHub\TraidingAlgorithm\venv\Lib\site-packages\urllib3\connectionpool.py", line 496, in _make_request
    conn.request(
  File "C:\Users\Andrew the master\Documents\GitHub\TraidingAlgorithm\venv\Lib\site-packages\urllib3\connection.py", line 395, in request
    self.endheaders()
  File "C:\Users\Andrew the master\AppData\Local\Programs\Python\Python311\Lib\http\client.py", line 1278, in endheaders
    self._send_output(message_body, encode_chunked=encode_chunked)
  File "C:\Users\Andrew the master\AppData\Local\Programs\Python\Python311\Lib\http\client.py", line 1038, in _send_output
    self.send(msg)
  File "C:\Users\Andrew the master\AppData\Local\Programs\Python\Python311\Lib\http\client.py", line 976, in send
    self.connect()
  File "C:\Users\Andrew the master\Documents\GitHub\TraidingAlgorithm\venv\Lib\site-packages\urllib3\connection.py", line 243, in connect
    self.sock = self._new_conn()
                ^^^^^^^^^^^^^^^^
  File "C:\Users\Andrew the master\Documents\GitHub\TraidingAlgorithm\venv\Lib\site-packages\urllib3\connection.py", line 218, in _new_conn
    raise NewConnectionError(
urllib3.exceptions.NewConnectionError: <urllib3.connection.HTTPConnection object at 0x0000021AFF9FD6D0>: Failed to establish a new connection: [WinError 10061] No connection could be made because the target machine actively refused it

The above exception was the direct cause of the following exception:

Traceback (most recent call last):
  File "C:\Users\Andrew the master\Documents\GitHub\TraidingAlgorithm\venv\Lib\site-packages\requests\adapters.py", line 486, in send
    resp = conn.urlopen(
           ^^^^^^^^^^^^^
  File "C:\Users\Andrew the master\Documents\GitHub\TraidingAlgorithm\venv\Lib\site-packages\urllib3\connectionpool.py", line 844, in urlopen
    retries = retries.increment(
              ^^^^^^^^^^^^^^^^^^
  File "C:\Users\Andrew the master\Documents\GitHub\TraidingAlgorithm\venv\Lib\site-packages\urllib3\util\retry.py", line 515, in increment
    raise MaxRetryError(_pool, url, reason) from reason  # type: ignore[arg-type]
    ^^^^^^^^^^^^^^^^^^^^^^^^^^^^^^^^^^^^^^^^^^^^^^^^^^^
urllib3.exceptions.MaxRetryError: HTTPConnectionPool(host='127.0.0.1', port=5000): Max retries exceeded with url: /api/v1/engulfing-pattern (Caused by NewConnectionError('<urllib3.connection.HTTPConnection object at 0x0000021AFF9FD6D0>: Failed to establish a new connection: [WinError 10061] No connection could be made because the target machine actively refused it'))

During handling of the above exception, another exception occurred:

Traceback (most recent call last):
  File "c:\Users\Andrew the master\Documents\GitHub\TraidingAlgorithm\main.py", line 906, in BTCUSDT_60min
    getAlert(dft2, '60min', 'Close', 28, 'HeikinAshi', symb)
  File "c:\Users\Andrew the master\Documents\GitHub\TraidingAlgorithm\main.py", line 278, in getAlert
    requests.post(url=url, data=data, headers=headers)
  File "C:\Users\Andrew the master\Documents\GitHub\TraidingAlgorithm\venv\Lib\site-packages\requests\api.py", line 115, in post
    return request("post", url, data=data, json=json, **kwargs)
           ^^^^^^^^^^^^^^^^^^^^^^^^^^^^^^^^^^^^^^^^^^^^^^^^^^^^
  File "C:\Users\Andrew the master\Documents\GitHub\TraidingAlgorithm\venv\Lib\site-packages\requests\api.py", line 59, in request
    return session.request(method=method, url=url, **kwargs)
           ^^^^^^^^^^^^^^^^^^^^^^^^^^^^^^^^^^^^^^^^^^^^^^^^^
  File "C:\Users\Andrew the master\Documents\GitHub\TraidingAlgorithm\venv\Lib\site-packages\requests\sessions.py", line 589, in request
    resp = self.send(prep, **send_kwargs)
           ^^^^^^^^^^^^^^^^^^^^^^^^^^^^^^
  File "C:\Users\Andrew the master\Documents\GitHub\TraidingAlgorithm\venv\Lib\site-packages\requests\sessions.py", line 703, in send
    r = adapter.send(request, **kwargs)
        ^^^^^^^^^^^^^^^^^^^^^^^^^^^^^^^
  File "C:\Users\Andrew the master\Documents\GitHub\TraidingAlgorithm\venv\Lib\site-packages\requests\adapters.py", line 519, in send
    raise ConnectionError(e, request=request)
requests.exceptions.ConnectionError: HTTPConnectionPool(host='127.0.0.1', port=5000): Max retries exceeded with url: /api/v1/engulfing-pattern (Caused by NewConnectionError('<urllib3.connection.HTTPConnection object at 0x0000021AFF9FD6D0>: Failed to establish a new connection: [WinError 10061] No connection could be made because the target machine actively refused it'))
2024-05-04 15:38:38,027 DEBUG Starting new HTTPS connection (1): api.bybit.com:443
2024-05-04 15:38:38,758 DEBUG https://api.bybit.com:443 "GET /v5/market/kline?category=spot&symbol=TOMIUSDT&interval=60&limit=300 HTTP/1.1" 200 22595
2024-05-04 15:38:38,979 DEBUG Starting new HTTPS connection (1): api.bybit.com:443
2024-05-04 15:38:39,334 DEBUG https://api.bybit.com:443 "GET /v5/market/kline?category=spot&symbol=TOMIUSDT&interval=60&limit=300 HTTP/1.1" 200 22595
2024-05-04 15:38:39,523 DEBUG Starting new HTTP connection (1): 127.0.0.1:5000
2024-05-04 15:38:41,571 ERROR 60min tf   
Traceback (most recent call last):
  File "C:\Users\Andrew the master\Documents\GitHub\TraidingAlgorithm\venv\Lib\site-packages\urllib3\connection.py", line 203, in _new_conn
    sock = connection.create_connection(
           ^^^^^^^^^^^^^^^^^^^^^^^^^^^^^
  File "C:\Users\Andrew the master\Documents\GitHub\TraidingAlgorithm\venv\Lib\site-packages\urllib3\util\connection.py", line 85, in create_connection
    raise err
  File "C:\Users\Andrew the master\Documents\GitHub\TraidingAlgorithm\venv\Lib\site-packages\urllib3\util\connection.py", line 73, in create_connection
    sock.connect(sa)
ConnectionRefusedError: [WinError 10061] No connection could be made because the target machine actively refused it

The above exception was the direct cause of the following exception:

Traceback (most recent call last):
  File "C:\Users\Andrew the master\Documents\GitHub\TraidingAlgorithm\venv\Lib\site-packages\urllib3\connectionpool.py", line 790, in urlopen
    response = self._make_request(
               ^^^^^^^^^^^^^^^^^^^
  File "C:\Users\Andrew the master\Documents\GitHub\TraidingAlgorithm\venv\Lib\site-packages\urllib3\connectionpool.py", line 496, in _make_request
    conn.request(
  File "C:\Users\Andrew the master\Documents\GitHub\TraidingAlgorithm\venv\Lib\site-packages\urllib3\connection.py", line 395, in request
    self.endheaders()
  File "C:\Users\Andrew the master\AppData\Local\Programs\Python\Python311\Lib\http\client.py", line 1278, in endheaders
    self._send_output(message_body, encode_chunked=encode_chunked)
  File "C:\Users\Andrew the master\AppData\Local\Programs\Python\Python311\Lib\http\client.py", line 1038, in _send_output
    self.send(msg)
  File "C:\Users\Andrew the master\AppData\Local\Programs\Python\Python311\Lib\http\client.py", line 976, in send
    self.connect()
  File "C:\Users\Andrew the master\Documents\GitHub\TraidingAlgorithm\venv\Lib\site-packages\urllib3\connection.py", line 243, in connect
    self.sock = self._new_conn()
                ^^^^^^^^^^^^^^^^
  File "C:\Users\Andrew the master\Documents\GitHub\TraidingAlgorithm\venv\Lib\site-packages\urllib3\connection.py", line 218, in _new_conn
    raise NewConnectionError(
urllib3.exceptions.NewConnectionError: <urllib3.connection.HTTPConnection object at 0x0000021AFFA4F710>: Failed to establish a new connection: [WinError 10061] No connection could be made because the target machine actively refused it

The above exception was the direct cause of the following exception:

Traceback (most recent call last):
  File "C:\Users\Andrew the master\Documents\GitHub\TraidingAlgorithm\venv\Lib\site-packages\requests\adapters.py", line 486, in send
    resp = conn.urlopen(
           ^^^^^^^^^^^^^
  File "C:\Users\Andrew the master\Documents\GitHub\TraidingAlgorithm\venv\Lib\site-packages\urllib3\connectionpool.py", line 844, in urlopen
    retries = retries.increment(
              ^^^^^^^^^^^^^^^^^^
  File "C:\Users\Andrew the master\Documents\GitHub\TraidingAlgorithm\venv\Lib\site-packages\urllib3\util\retry.py", line 515, in increment
    raise MaxRetryError(_pool, url, reason) from reason  # type: ignore[arg-type]
    ^^^^^^^^^^^^^^^^^^^^^^^^^^^^^^^^^^^^^^^^^^^^^^^^^^^
urllib3.exceptions.MaxRetryError: HTTPConnectionPool(host='127.0.0.1', port=5000): Max retries exceeded with url: /api/v1/engulfing-pattern (Caused by NewConnectionError('<urllib3.connection.HTTPConnection object at 0x0000021AFFA4F710>: Failed to establish a new connection: [WinError 10061] No connection could be made because the target machine actively refused it'))

During handling of the above exception, another exception occurred:

Traceback (most recent call last):
  File "c:\Users\Andrew the master\Documents\GitHub\TraidingAlgorithm\main.py", line 906, in BTCUSDT_60min
    getAlert(dft2, '60min', 'Close', 28, 'HeikinAshi', symb)
  File "c:\Users\Andrew the master\Documents\GitHub\TraidingAlgorithm\main.py", line 278, in getAlert
    requests.post(url=url, data=data, headers=headers)
  File "C:\Users\Andrew the master\Documents\GitHub\TraidingAlgorithm\venv\Lib\site-packages\requests\api.py", line 115, in post
    return request("post", url, data=data, json=json, **kwargs)
           ^^^^^^^^^^^^^^^^^^^^^^^^^^^^^^^^^^^^^^^^^^^^^^^^^^^^
  File "C:\Users\Andrew the master\Documents\GitHub\TraidingAlgorithm\venv\Lib\site-packages\requests\api.py", line 59, in request
    return session.request(method=method, url=url, **kwargs)
           ^^^^^^^^^^^^^^^^^^^^^^^^^^^^^^^^^^^^^^^^^^^^^^^^^
  File "C:\Users\Andrew the master\Documents\GitHub\TraidingAlgorithm\venv\Lib\site-packages\requests\sessions.py", line 589, in request
    resp = self.send(prep, **send_kwargs)
           ^^^^^^^^^^^^^^^^^^^^^^^^^^^^^^
  File "C:\Users\Andrew the master\Documents\GitHub\TraidingAlgorithm\venv\Lib\site-packages\requests\sessions.py", line 703, in send
    r = adapter.send(request, **kwargs)
        ^^^^^^^^^^^^^^^^^^^^^^^^^^^^^^^
  File "C:\Users\Andrew the master\Documents\GitHub\TraidingAlgorithm\venv\Lib\site-packages\requests\adapters.py", line 519, in send
    raise ConnectionError(e, request=request)
requests.exceptions.ConnectionError: HTTPConnectionPool(host='127.0.0.1', port=5000): Max retries exceeded with url: /api/v1/engulfing-pattern (Caused by NewConnectionError('<urllib3.connection.HTTPConnection object at 0x0000021AFFA4F710>: Failed to establish a new connection: [WinError 10061] No connection could be made because the target machine actively refused it'))
2024-05-04 15:38:41,574 DEBUG Starting new HTTPS connection (1): api.bybit.com:443
2024-05-04 15:38:42,471 DEBUG https://api.bybit.com:443 "GET /v5/market/kline?category=spot&symbol=MATICUSDT&interval=60&limit=300 HTTP/1.1" 200 24638
2024-05-04 15:38:42,478 DEBUG Starting new HTTPS connection (1): api.bybit.com:443
2024-05-04 15:38:42,776 DEBUG https://api.bybit.com:443 "GET /v5/market/kline?category=spot&symbol=MATICUSDT&interval=60&limit=300 HTTP/1.1" 200 24638
2024-05-04 15:38:42,996 DEBUG Starting new HTTP connection (1): 127.0.0.1:5000
2024-05-04 15:38:45,038 ERROR 60min tf   
Traceback (most recent call last):
  File "C:\Users\Andrew the master\Documents\GitHub\TraidingAlgorithm\venv\Lib\site-packages\urllib3\connection.py", line 203, in _new_conn
    sock = connection.create_connection(
           ^^^^^^^^^^^^^^^^^^^^^^^^^^^^^
  File "C:\Users\Andrew the master\Documents\GitHub\TraidingAlgorithm\venv\Lib\site-packages\urllib3\util\connection.py", line 85, in create_connection
    raise err
  File "C:\Users\Andrew the master\Documents\GitHub\TraidingAlgorithm\venv\Lib\site-packages\urllib3\util\connection.py", line 73, in create_connection
    sock.connect(sa)
ConnectionRefusedError: [WinError 10061] No connection could be made because the target machine actively refused it

The above exception was the direct cause of the following exception:

Traceback (most recent call last):
  File "C:\Users\Andrew the master\Documents\GitHub\TraidingAlgorithm\venv\Lib\site-packages\urllib3\connectionpool.py", line 790, in urlopen
    response = self._make_request(
               ^^^^^^^^^^^^^^^^^^^
  File "C:\Users\Andrew the master\Documents\GitHub\TraidingAlgorithm\venv\Lib\site-packages\urllib3\connectionpool.py", line 496, in _make_request
    conn.request(
  File "C:\Users\Andrew the master\Documents\GitHub\TraidingAlgorithm\venv\Lib\site-packages\urllib3\connection.py", line 395, in request
    self.endheaders()
  File "C:\Users\Andrew the master\AppData\Local\Programs\Python\Python311\Lib\http\client.py", line 1278, in endheaders
    self._send_output(message_body, encode_chunked=encode_chunked)
  File "C:\Users\Andrew the master\AppData\Local\Programs\Python\Python311\Lib\http\client.py", line 1038, in _send_output
    self.send(msg)
  File "C:\Users\Andrew the master\AppData\Local\Programs\Python\Python311\Lib\http\client.py", line 976, in send
    self.connect()
  File "C:\Users\Andrew the master\Documents\GitHub\TraidingAlgorithm\venv\Lib\site-packages\urllib3\connection.py", line 243, in connect
    self.sock = self._new_conn()
                ^^^^^^^^^^^^^^^^
  File "C:\Users\Andrew the master\Documents\GitHub\TraidingAlgorithm\venv\Lib\site-packages\urllib3\connection.py", line 218, in _new_conn
    raise NewConnectionError(
urllib3.exceptions.NewConnectionError: <urllib3.connection.HTTPConnection object at 0x0000021AFFA64610>: Failed to establish a new connection: [WinError 10061] No connection could be made because the target machine actively refused it

The above exception was the direct cause of the following exception:

Traceback (most recent call last):
  File "C:\Users\Andrew the master\Documents\GitHub\TraidingAlgorithm\venv\Lib\site-packages\requests\adapters.py", line 486, in send
    resp = conn.urlopen(
           ^^^^^^^^^^^^^
  File "C:\Users\Andrew the master\Documents\GitHub\TraidingAlgorithm\venv\Lib\site-packages\urllib3\connectionpool.py", line 844, in urlopen
    retries = retries.increment(
              ^^^^^^^^^^^^^^^^^^
  File "C:\Users\Andrew the master\Documents\GitHub\TraidingAlgorithm\venv\Lib\site-packages\urllib3\util\retry.py", line 515, in increment
    raise MaxRetryError(_pool, url, reason) from reason  # type: ignore[arg-type]
    ^^^^^^^^^^^^^^^^^^^^^^^^^^^^^^^^^^^^^^^^^^^^^^^^^^^
urllib3.exceptions.MaxRetryError: HTTPConnectionPool(host='127.0.0.1', port=5000): Max retries exceeded with url: /api/v1/engulfing-pattern (Caused by NewConnectionError('<urllib3.connection.HTTPConnection object at 0x0000021AFFA64610>: Failed to establish a new connection: [WinError 10061] No connection could be made because the target machine actively refused it'))

During handling of the above exception, another exception occurred:

Traceback (most recent call last):
  File "c:\Users\Andrew the master\Documents\GitHub\TraidingAlgorithm\main.py", line 906, in BTCUSDT_60min
    getAlert(dft2, '60min', 'Close', 28, 'HeikinAshi', symb)
  File "c:\Users\Andrew the master\Documents\GitHub\TraidingAlgorithm\main.py", line 278, in getAlert
    requests.post(url=url, data=data, headers=headers)
  File "C:\Users\Andrew the master\Documents\GitHub\TraidingAlgorithm\venv\Lib\site-packages\requests\api.py", line 115, in post
    return request("post", url, data=data, json=json, **kwargs)
           ^^^^^^^^^^^^^^^^^^^^^^^^^^^^^^^^^^^^^^^^^^^^^^^^^^^^
  File "C:\Users\Andrew the master\Documents\GitHub\TraidingAlgorithm\venv\Lib\site-packages\requests\api.py", line 59, in request
    return session.request(method=method, url=url, **kwargs)
           ^^^^^^^^^^^^^^^^^^^^^^^^^^^^^^^^^^^^^^^^^^^^^^^^^
  File "C:\Users\Andrew the master\Documents\GitHub\TraidingAlgorithm\venv\Lib\site-packages\requests\sessions.py", line 589, in request
    resp = self.send(prep, **send_kwargs)
           ^^^^^^^^^^^^^^^^^^^^^^^^^^^^^^
  File "C:\Users\Andrew the master\Documents\GitHub\TraidingAlgorithm\venv\Lib\site-packages\requests\sessions.py", line 703, in send
    r = adapter.send(request, **kwargs)
        ^^^^^^^^^^^^^^^^^^^^^^^^^^^^^^^
  File "C:\Users\Andrew the master\Documents\GitHub\TraidingAlgorithm\venv\Lib\site-packages\requests\adapters.py", line 519, in send
    raise ConnectionError(e, request=request)
requests.exceptions.ConnectionError: HTTPConnectionPool(host='127.0.0.1', port=5000): Max retries exceeded with url: /api/v1/engulfing-pattern (Caused by NewConnectionError('<urllib3.connection.HTTPConnection object at 0x0000021AFFA64610>: Failed to establish a new connection: [WinError 10061] No connection could be made because the target machine actively refused it'))
2024-05-04 15:38:45,042 DEBUG Starting new HTTPS connection (1): api.bybit.com:443
2024-05-04 15:38:45,732 DEBUG https://api.bybit.com:443 "GET /v5/market/kline?category=spot&symbol=AVAXUSDT&interval=60&limit=300 HTTP/1.1" 200 25906
2024-05-04 15:38:45,934 DEBUG Starting new HTTPS connection (1): api.bybit.com:443
2024-05-04 15:38:46,757 DEBUG https://api.bybit.com:443 "GET /v5/market/kline?category=spot&symbol=AVAXUSDT&interval=60&limit=300 HTTP/1.1" 200 25906
2024-05-04 15:38:47,229 DEBUG Starting new HTTP connection (1): 127.0.0.1:5000
2024-05-04 15:38:49,283 ERROR 60min tf   
Traceback (most recent call last):
  File "C:\Users\Andrew the master\Documents\GitHub\TraidingAlgorithm\venv\Lib\site-packages\urllib3\connection.py", line 203, in _new_conn
    sock = connection.create_connection(
           ^^^^^^^^^^^^^^^^^^^^^^^^^^^^^
  File "C:\Users\Andrew the master\Documents\GitHub\TraidingAlgorithm\venv\Lib\site-packages\urllib3\util\connection.py", line 85, in create_connection
    raise err
  File "C:\Users\Andrew the master\Documents\GitHub\TraidingAlgorithm\venv\Lib\site-packages\urllib3\util\connection.py", line 73, in create_connection
    sock.connect(sa)
ConnectionRefusedError: [WinError 10061] No connection could be made because the target machine actively refused it

The above exception was the direct cause of the following exception:

Traceback (most recent call last):
  File "C:\Users\Andrew the master\Documents\GitHub\TraidingAlgorithm\venv\Lib\site-packages\urllib3\connectionpool.py", line 790, in urlopen
    response = self._make_request(
               ^^^^^^^^^^^^^^^^^^^
  File "C:\Users\Andrew the master\Documents\GitHub\TraidingAlgorithm\venv\Lib\site-packages\urllib3\connectionpool.py", line 496, in _make_request
    conn.request(
  File "C:\Users\Andrew the master\Documents\GitHub\TraidingAlgorithm\venv\Lib\site-packages\urllib3\connection.py", line 395, in request
    self.endheaders()
  File "C:\Users\Andrew the master\AppData\Local\Programs\Python\Python311\Lib\http\client.py", line 1278, in endheaders
    self._send_output(message_body, encode_chunked=encode_chunked)
  File "C:\Users\Andrew the master\AppData\Local\Programs\Python\Python311\Lib\http\client.py", line 1038, in _send_output
    self.send(msg)
  File "C:\Users\Andrew the master\AppData\Local\Programs\Python\Python311\Lib\http\client.py", line 976, in send
    self.connect()
  File "C:\Users\Andrew the master\Documents\GitHub\TraidingAlgorithm\venv\Lib\site-packages\urllib3\connection.py", line 243, in connect
    self.sock = self._new_conn()
                ^^^^^^^^^^^^^^^^
  File "C:\Users\Andrew the master\Documents\GitHub\TraidingAlgorithm\venv\Lib\site-packages\urllib3\connection.py", line 218, in _new_conn
    raise NewConnectionError(
urllib3.exceptions.NewConnectionError: <urllib3.connection.HTTPConnection object at 0x0000021AFFA356D0>: Failed to establish a new connection: [WinError 10061] No connection could be made because the target machine actively refused it

The above exception was the direct cause of the following exception:

Traceback (most recent call last):
  File "C:\Users\Andrew the master\Documents\GitHub\TraidingAlgorithm\venv\Lib\site-packages\requests\adapters.py", line 486, in send
    resp = conn.urlopen(
           ^^^^^^^^^^^^^
  File "C:\Users\Andrew the master\Documents\GitHub\TraidingAlgorithm\venv\Lib\site-packages\urllib3\connectionpool.py", line 844, in urlopen
    retries = retries.increment(
              ^^^^^^^^^^^^^^^^^^
  File "C:\Users\Andrew the master\Documents\GitHub\TraidingAlgorithm\venv\Lib\site-packages\urllib3\util\retry.py", line 515, in increment
    raise MaxRetryError(_pool, url, reason) from reason  # type: ignore[arg-type]
    ^^^^^^^^^^^^^^^^^^^^^^^^^^^^^^^^^^^^^^^^^^^^^^^^^^^
urllib3.exceptions.MaxRetryError: HTTPConnectionPool(host='127.0.0.1', port=5000): Max retries exceeded with url: /api/v1/engulfing-pattern (Caused by NewConnectionError('<urllib3.connection.HTTPConnection object at 0x0000021AFFA356D0>: Failed to establish a new connection: [WinError 10061] No connection could be made because the target machine actively refused it'))

During handling of the above exception, another exception occurred:

Traceback (most recent call last):
  File "c:\Users\Andrew the master\Documents\GitHub\TraidingAlgorithm\main.py", line 906, in BTCUSDT_60min
    getAlert(dft2, '60min', 'Close', 28, 'HeikinAshi', symb)
  File "c:\Users\Andrew the master\Documents\GitHub\TraidingAlgorithm\main.py", line 278, in getAlert
    requests.post(url=url, data=data, headers=headers)
  File "C:\Users\Andrew the master\Documents\GitHub\TraidingAlgorithm\venv\Lib\site-packages\requests\api.py", line 115, in post
    return request("post", url, data=data, json=json, **kwargs)
           ^^^^^^^^^^^^^^^^^^^^^^^^^^^^^^^^^^^^^^^^^^^^^^^^^^^^
  File "C:\Users\Andrew the master\Documents\GitHub\TraidingAlgorithm\venv\Lib\site-packages\requests\api.py", line 59, in request
    return session.request(method=method, url=url, **kwargs)
           ^^^^^^^^^^^^^^^^^^^^^^^^^^^^^^^^^^^^^^^^^^^^^^^^^
  File "C:\Users\Andrew the master\Documents\GitHub\TraidingAlgorithm\venv\Lib\site-packages\requests\sessions.py", line 589, in request
    resp = self.send(prep, **send_kwargs)
           ^^^^^^^^^^^^^^^^^^^^^^^^^^^^^^
  File "C:\Users\Andrew the master\Documents\GitHub\TraidingAlgorithm\venv\Lib\site-packages\requests\sessions.py", line 703, in send
    r = adapter.send(request, **kwargs)
        ^^^^^^^^^^^^^^^^^^^^^^^^^^^^^^^
  File "C:\Users\Andrew the master\Documents\GitHub\TraidingAlgorithm\venv\Lib\site-packages\requests\adapters.py", line 519, in send
    raise ConnectionError(e, request=request)
requests.exceptions.ConnectionError: HTTPConnectionPool(host='127.0.0.1', port=5000): Max retries exceeded with url: /api/v1/engulfing-pattern (Caused by NewConnectionError('<urllib3.connection.HTTPConnection object at 0x0000021AFFA356D0>: Failed to establish a new connection: [WinError 10061] No connection could be made because the target machine actively refused it'))
2024-05-04 15:38:49,287 DEBUG Starting new HTTPS connection (1): api.bybit.com:443
2024-05-04 15:38:49,788 DEBUG https://api.bybit.com:443 "GET /v5/market/kline?category=spot&symbol=DOTUSDT&interval=60&limit=300 HTTP/1.1" 200 23382
2024-05-04 15:38:49,795 DEBUG Starting new HTTPS connection (1): api.bybit.com:443
2024-05-04 15:38:50,091 DEBUG https://api.bybit.com:443 "GET /v5/market/kline?category=spot&symbol=DOTUSDT&interval=60&limit=300 HTTP/1.1" 200 23382
2024-05-04 15:38:50,412 DEBUG Starting new HTTP connection (1): 127.0.0.1:5000
2024-05-04 15:38:52,460 ERROR 60min tf   
Traceback (most recent call last):
  File "C:\Users\Andrew the master\Documents\GitHub\TraidingAlgorithm\venv\Lib\site-packages\urllib3\connection.py", line 203, in _new_conn
    sock = connection.create_connection(
           ^^^^^^^^^^^^^^^^^^^^^^^^^^^^^
  File "C:\Users\Andrew the master\Documents\GitHub\TraidingAlgorithm\venv\Lib\site-packages\urllib3\util\connection.py", line 85, in create_connection
    raise err
  File "C:\Users\Andrew the master\Documents\GitHub\TraidingAlgorithm\venv\Lib\site-packages\urllib3\util\connection.py", line 73, in create_connection
    sock.connect(sa)
ConnectionRefusedError: [WinError 10061] No connection could be made because the target machine actively refused it

The above exception was the direct cause of the following exception:

Traceback (most recent call last):
  File "C:\Users\Andrew the master\Documents\GitHub\TraidingAlgorithm\venv\Lib\site-packages\urllib3\connectionpool.py", line 790, in urlopen
    response = self._make_request(
               ^^^^^^^^^^^^^^^^^^^
  File "C:\Users\Andrew the master\Documents\GitHub\TraidingAlgorithm\venv\Lib\site-packages\urllib3\connectionpool.py", line 496, in _make_request
    conn.request(
  File "C:\Users\Andrew the master\Documents\GitHub\TraidingAlgorithm\venv\Lib\site-packages\urllib3\connection.py", line 395, in request
    self.endheaders()
  File "C:\Users\Andrew the master\AppData\Local\Programs\Python\Python311\Lib\http\client.py", line 1278, in endheaders
    self._send_output(message_body, encode_chunked=encode_chunked)
  File "C:\Users\Andrew the master\AppData\Local\Programs\Python\Python311\Lib\http\client.py", line 1038, in _send_output
    self.send(msg)
  File "C:\Users\Andrew the master\AppData\Local\Programs\Python\Python311\Lib\http\client.py", line 976, in send
    self.connect()
  File "C:\Users\Andrew the master\Documents\GitHub\TraidingAlgorithm\venv\Lib\site-packages\urllib3\connection.py", line 243, in connect
    self.sock = self._new_conn()
                ^^^^^^^^^^^^^^^^
  File "C:\Users\Andrew the master\Documents\GitHub\TraidingAlgorithm\venv\Lib\site-packages\urllib3\connection.py", line 218, in _new_conn
    raise NewConnectionError(
urllib3.exceptions.NewConnectionError: <urllib3.connection.HTTPConnection object at 0x0000021AFFB2D9D0>: Failed to establish a new connection: [WinError 10061] No connection could be made because the target machine actively refused it

The above exception was the direct cause of the following exception:

Traceback (most recent call last):
  File "C:\Users\Andrew the master\Documents\GitHub\TraidingAlgorithm\venv\Lib\site-packages\requests\adapters.py", line 486, in send
    resp = conn.urlopen(
           ^^^^^^^^^^^^^
  File "C:\Users\Andrew the master\Documents\GitHub\TraidingAlgorithm\venv\Lib\site-packages\urllib3\connectionpool.py", line 844, in urlopen
    retries = retries.increment(
              ^^^^^^^^^^^^^^^^^^
  File "C:\Users\Andrew the master\Documents\GitHub\TraidingAlgorithm\venv\Lib\site-packages\urllib3\util\retry.py", line 515, in increment
    raise MaxRetryError(_pool, url, reason) from reason  # type: ignore[arg-type]
    ^^^^^^^^^^^^^^^^^^^^^^^^^^^^^^^^^^^^^^^^^^^^^^^^^^^
urllib3.exceptions.MaxRetryError: HTTPConnectionPool(host='127.0.0.1', port=5000): Max retries exceeded with url: /api/v1/engulfing-pattern (Caused by NewConnectionError('<urllib3.connection.HTTPConnection object at 0x0000021AFFB2D9D0>: Failed to establish a new connection: [WinError 10061] No connection could be made because the target machine actively refused it'))

During handling of the above exception, another exception occurred:

Traceback (most recent call last):
  File "c:\Users\Andrew the master\Documents\GitHub\TraidingAlgorithm\main.py", line 906, in BTCUSDT_60min
    getAlert(dft2, '60min', 'Close', 28, 'HeikinAshi', symb)
  File "c:\Users\Andrew the master\Documents\GitHub\TraidingAlgorithm\main.py", line 278, in getAlert
    requests.post(url=url, data=data, headers=headers)
  File "C:\Users\Andrew the master\Documents\GitHub\TraidingAlgorithm\venv\Lib\site-packages\requests\api.py", line 115, in post
    return request("post", url, data=data, json=json, **kwargs)
           ^^^^^^^^^^^^^^^^^^^^^^^^^^^^^^^^^^^^^^^^^^^^^^^^^^^^
  File "C:\Users\Andrew the master\Documents\GitHub\TraidingAlgorithm\venv\Lib\site-packages\requests\api.py", line 59, in request
    return session.request(method=method, url=url, **kwargs)
           ^^^^^^^^^^^^^^^^^^^^^^^^^^^^^^^^^^^^^^^^^^^^^^^^^
  File "C:\Users\Andrew the master\Documents\GitHub\TraidingAlgorithm\venv\Lib\site-packages\requests\sessions.py", line 589, in request
    resp = self.send(prep, **send_kwargs)
           ^^^^^^^^^^^^^^^^^^^^^^^^^^^^^^
  File "C:\Users\Andrew the master\Documents\GitHub\TraidingAlgorithm\venv\Lib\site-packages\requests\sessions.py", line 703, in send
    r = adapter.send(request, **kwargs)
        ^^^^^^^^^^^^^^^^^^^^^^^^^^^^^^^
  File "C:\Users\Andrew the master\Documents\GitHub\TraidingAlgorithm\venv\Lib\site-packages\requests\adapters.py", line 519, in send
    raise ConnectionError(e, request=request)
requests.exceptions.ConnectionError: HTTPConnectionPool(host='127.0.0.1', port=5000): Max retries exceeded with url: /api/v1/engulfing-pattern (Caused by NewConnectionError('<urllib3.connection.HTTPConnection object at 0x0000021AFFB2D9D0>: Failed to establish a new connection: [WinError 10061] No connection could be made because the target machine actively refused it'))
2024-05-04 15:38:52,465 DEBUG Starting new HTTPS connection (1): api.bybit.com:443
2024-05-04 15:38:52,763 DEBUG https://api.bybit.com:443 "GET /v5/market/kline?category=spot&symbol=BTCUSDT&interval=30&limit=300 HTTP/1.1" 200 28193
2024-05-04 15:38:52,978 DEBUG Starting new HTTPS connection (1): api.bybit.com:443
2024-05-04 15:38:53,500 DEBUG https://api.bybit.com:443 "GET /v5/market/kline?category=spot&symbol=BTCUSDT&interval=30&limit=300 HTTP/1.1" 200 28193
2024-05-04 15:38:53,774 DEBUG Starting new HTTP connection (1): 127.0.0.1:5000
2024-05-04 15:38:55,817 ERROR 30min tf   
Traceback (most recent call last):
  File "C:\Users\Andrew the master\Documents\GitHub\TraidingAlgorithm\venv\Lib\site-packages\urllib3\connection.py", line 203, in _new_conn
    sock = connection.create_connection(
           ^^^^^^^^^^^^^^^^^^^^^^^^^^^^^
  File "C:\Users\Andrew the master\Documents\GitHub\TraidingAlgorithm\venv\Lib\site-packages\urllib3\util\connection.py", line 85, in create_connection
    raise err
  File "C:\Users\Andrew the master\Documents\GitHub\TraidingAlgorithm\venv\Lib\site-packages\urllib3\util\connection.py", line 73, in create_connection
    sock.connect(sa)
ConnectionRefusedError: [WinError 10061] No connection could be made because the target machine actively refused it

The above exception was the direct cause of the following exception:

Traceback (most recent call last):
  File "C:\Users\Andrew the master\Documents\GitHub\TraidingAlgorithm\venv\Lib\site-packages\urllib3\connectionpool.py", line 790, in urlopen
    response = self._make_request(
               ^^^^^^^^^^^^^^^^^^^
  File "C:\Users\Andrew the master\Documents\GitHub\TraidingAlgorithm\venv\Lib\site-packages\urllib3\connectionpool.py", line 496, in _make_request
    conn.request(
  File "C:\Users\Andrew the master\Documents\GitHub\TraidingAlgorithm\venv\Lib\site-packages\urllib3\connection.py", line 395, in request
    self.endheaders()
  File "C:\Users\Andrew the master\AppData\Local\Programs\Python\Python311\Lib\http\client.py", line 1278, in endheaders
    self._send_output(message_body, encode_chunked=encode_chunked)
  File "C:\Users\Andrew the master\AppData\Local\Programs\Python\Python311\Lib\http\client.py", line 1038, in _send_output
    self.send(msg)
  File "C:\Users\Andrew the master\AppData\Local\Programs\Python\Python311\Lib\http\client.py", line 976, in send
    self.connect()
  File "C:\Users\Andrew the master\Documents\GitHub\TraidingAlgorithm\venv\Lib\site-packages\urllib3\connection.py", line 243, in connect
    self.sock = self._new_conn()
                ^^^^^^^^^^^^^^^^
  File "C:\Users\Andrew the master\Documents\GitHub\TraidingAlgorithm\venv\Lib\site-packages\urllib3\connection.py", line 218, in _new_conn
    raise NewConnectionError(
urllib3.exceptions.NewConnectionError: <urllib3.connection.HTTPConnection object at 0x0000021AFFA3A210>: Failed to establish a new connection: [WinError 10061] No connection could be made because the target machine actively refused it

The above exception was the direct cause of the following exception:

Traceback (most recent call last):
  File "C:\Users\Andrew the master\Documents\GitHub\TraidingAlgorithm\venv\Lib\site-packages\requests\adapters.py", line 486, in send
    resp = conn.urlopen(
           ^^^^^^^^^^^^^
  File "C:\Users\Andrew the master\Documents\GitHub\TraidingAlgorithm\venv\Lib\site-packages\urllib3\connectionpool.py", line 844, in urlopen
    retries = retries.increment(
              ^^^^^^^^^^^^^^^^^^
  File "C:\Users\Andrew the master\Documents\GitHub\TraidingAlgorithm\venv\Lib\site-packages\urllib3\util\retry.py", line 515, in increment
    raise MaxRetryError(_pool, url, reason) from reason  # type: ignore[arg-type]
    ^^^^^^^^^^^^^^^^^^^^^^^^^^^^^^^^^^^^^^^^^^^^^^^^^^^
urllib3.exceptions.MaxRetryError: HTTPConnectionPool(host='127.0.0.1', port=5000): Max retries exceeded with url: /api/v1/engulfing-pattern (Caused by NewConnectionError('<urllib3.connection.HTTPConnection object at 0x0000021AFFA3A210>: Failed to establish a new connection: [WinError 10061] No connection could be made because the target machine actively refused it'))

During handling of the above exception, another exception occurred:

Traceback (most recent call last):
  File "c:\Users\Andrew the master\Documents\GitHub\TraidingAlgorithm\main.py", line 888, in BTCUSDT_30min
    getAlert(dft2, '30min', 'Close', 28, 'HeikinAshi', symb)
  File "c:\Users\Andrew the master\Documents\GitHub\TraidingAlgorithm\main.py", line 278, in getAlert
    requests.post(url=url, data=data, headers=headers)
  File "C:\Users\Andrew the master\Documents\GitHub\TraidingAlgorithm\venv\Lib\site-packages\requests\api.py", line 115, in post
    return request("post", url, data=data, json=json, **kwargs)
           ^^^^^^^^^^^^^^^^^^^^^^^^^^^^^^^^^^^^^^^^^^^^^^^^^^^^
  File "C:\Users\Andrew the master\Documents\GitHub\TraidingAlgorithm\venv\Lib\site-packages\requests\api.py", line 59, in request
    return session.request(method=method, url=url, **kwargs)
           ^^^^^^^^^^^^^^^^^^^^^^^^^^^^^^^^^^^^^^^^^^^^^^^^^
  File "C:\Users\Andrew the master\Documents\GitHub\TraidingAlgorithm\venv\Lib\site-packages\requests\sessions.py", line 589, in request
    resp = self.send(prep, **send_kwargs)
           ^^^^^^^^^^^^^^^^^^^^^^^^^^^^^^
  File "C:\Users\Andrew the master\Documents\GitHub\TraidingAlgorithm\venv\Lib\site-packages\requests\sessions.py", line 703, in send
    r = adapter.send(request, **kwargs)
        ^^^^^^^^^^^^^^^^^^^^^^^^^^^^^^^
  File "C:\Users\Andrew the master\Documents\GitHub\TraidingAlgorithm\venv\Lib\site-packages\requests\adapters.py", line 519, in send
    raise ConnectionError(e, request=request)
requests.exceptions.ConnectionError: HTTPConnectionPool(host='127.0.0.1', port=5000): Max retries exceeded with url: /api/v1/engulfing-pattern (Caused by NewConnectionError('<urllib3.connection.HTTPConnection object at 0x0000021AFFA3A210>: Failed to establish a new connection: [WinError 10061] No connection could be made because the target machine actively refused it'))
2024-05-04 15:38:55,821 DEBUG Starting new HTTPS connection (1): api.bybit.com:443
2024-05-04 15:38:56,744 DEBUG https://api.bybit.com:443 "GET /v5/market/kline?category=spot&symbol=ETHUSDT&interval=30&limit=300 HTTP/1.1" 200 26698
2024-05-04 15:38:56,753 DEBUG Starting new HTTPS connection (1): api.bybit.com:443
2024-05-04 15:38:57,648 DEBUG https://api.bybit.com:443 "GET /v5/market/kline?category=spot&symbol=ETHUSDT&interval=30&limit=300 HTTP/1.1" 200 26698
2024-05-04 15:38:57,947 DEBUG Starting new HTTP connection (1): 127.0.0.1:5000
2024-05-04 15:38:59,989 ERROR 30min tf   
Traceback (most recent call last):
  File "C:\Users\Andrew the master\Documents\GitHub\TraidingAlgorithm\venv\Lib\site-packages\urllib3\connection.py", line 203, in _new_conn
    sock = connection.create_connection(
           ^^^^^^^^^^^^^^^^^^^^^^^^^^^^^
  File "C:\Users\Andrew the master\Documents\GitHub\TraidingAlgorithm\venv\Lib\site-packages\urllib3\util\connection.py", line 85, in create_connection
    raise err
  File "C:\Users\Andrew the master\Documents\GitHub\TraidingAlgorithm\venv\Lib\site-packages\urllib3\util\connection.py", line 73, in create_connection
    sock.connect(sa)
ConnectionRefusedError: [WinError 10061] No connection could be made because the target machine actively refused it

The above exception was the direct cause of the following exception:

Traceback (most recent call last):
  File "C:\Users\Andrew the master\Documents\GitHub\TraidingAlgorithm\venv\Lib\site-packages\urllib3\connectionpool.py", line 790, in urlopen
    response = self._make_request(
               ^^^^^^^^^^^^^^^^^^^
  File "C:\Users\Andrew the master\Documents\GitHub\TraidingAlgorithm\venv\Lib\site-packages\urllib3\connectionpool.py", line 496, in _make_request
    conn.request(
  File "C:\Users\Andrew the master\Documents\GitHub\TraidingAlgorithm\venv\Lib\site-packages\urllib3\connection.py", line 395, in request
    self.endheaders()
  File "C:\Users\Andrew the master\AppData\Local\Programs\Python\Python311\Lib\http\client.py", line 1278, in endheaders
    self._send_output(message_body, encode_chunked=encode_chunked)
  File "C:\Users\Andrew the master\AppData\Local\Programs\Python\Python311\Lib\http\client.py", line 1038, in _send_output
    self.send(msg)
  File "C:\Users\Andrew the master\AppData\Local\Programs\Python\Python311\Lib\http\client.py", line 976, in send
    self.connect()
  File "C:\Users\Andrew the master\Documents\GitHub\TraidingAlgorithm\venv\Lib\site-packages\urllib3\connection.py", line 243, in connect
    self.sock = self._new_conn()
                ^^^^^^^^^^^^^^^^
  File "C:\Users\Andrew the master\Documents\GitHub\TraidingAlgorithm\venv\Lib\site-packages\urllib3\connection.py", line 218, in _new_conn
    raise NewConnectionError(
urllib3.exceptions.NewConnectionError: <urllib3.connection.HTTPConnection object at 0x0000021AFF9EA050>: Failed to establish a new connection: [WinError 10061] No connection could be made because the target machine actively refused it

The above exception was the direct cause of the following exception:

Traceback (most recent call last):
  File "C:\Users\Andrew the master\Documents\GitHub\TraidingAlgorithm\venv\Lib\site-packages\requests\adapters.py", line 486, in send
    resp = conn.urlopen(
           ^^^^^^^^^^^^^
  File "C:\Users\Andrew the master\Documents\GitHub\TraidingAlgorithm\venv\Lib\site-packages\urllib3\connectionpool.py", line 844, in urlopen
    retries = retries.increment(
              ^^^^^^^^^^^^^^^^^^
  File "C:\Users\Andrew the master\Documents\GitHub\TraidingAlgorithm\venv\Lib\site-packages\urllib3\util\retry.py", line 515, in increment
    raise MaxRetryError(_pool, url, reason) from reason  # type: ignore[arg-type]
    ^^^^^^^^^^^^^^^^^^^^^^^^^^^^^^^^^^^^^^^^^^^^^^^^^^^
urllib3.exceptions.MaxRetryError: HTTPConnectionPool(host='127.0.0.1', port=5000): Max retries exceeded with url: /api/v1/engulfing-pattern (Caused by NewConnectionError('<urllib3.connection.HTTPConnection object at 0x0000021AFF9EA050>: Failed to establish a new connection: [WinError 10061] No connection could be made because the target machine actively refused it'))

During handling of the above exception, another exception occurred:

Traceback (most recent call last):
  File "c:\Users\Andrew the master\Documents\GitHub\TraidingAlgorithm\main.py", line 888, in BTCUSDT_30min
    getAlert(dft2, '30min', 'Close', 28, 'HeikinAshi', symb)
  File "c:\Users\Andrew the master\Documents\GitHub\TraidingAlgorithm\main.py", line 278, in getAlert
    requests.post(url=url, data=data, headers=headers)
  File "C:\Users\Andrew the master\Documents\GitHub\TraidingAlgorithm\venv\Lib\site-packages\requests\api.py", line 115, in post
    return request("post", url, data=data, json=json, **kwargs)
           ^^^^^^^^^^^^^^^^^^^^^^^^^^^^^^^^^^^^^^^^^^^^^^^^^^^^
  File "C:\Users\Andrew the master\Documents\GitHub\TraidingAlgorithm\venv\Lib\site-packages\requests\api.py", line 59, in request
    return session.request(method=method, url=url, **kwargs)
           ^^^^^^^^^^^^^^^^^^^^^^^^^^^^^^^^^^^^^^^^^^^^^^^^^
  File "C:\Users\Andrew the master\Documents\GitHub\TraidingAlgorithm\venv\Lib\site-packages\requests\sessions.py", line 589, in request
    resp = self.send(prep, **send_kwargs)
           ^^^^^^^^^^^^^^^^^^^^^^^^^^^^^^
  File "C:\Users\Andrew the master\Documents\GitHub\TraidingAlgorithm\venv\Lib\site-packages\requests\sessions.py", line 703, in send
    r = adapter.send(request, **kwargs)
        ^^^^^^^^^^^^^^^^^^^^^^^^^^^^^^^
  File "C:\Users\Andrew the master\Documents\GitHub\TraidingAlgorithm\venv\Lib\site-packages\requests\adapters.py", line 519, in send
    raise ConnectionError(e, request=request)
requests.exceptions.ConnectionError: HTTPConnectionPool(host='127.0.0.1', port=5000): Max retries exceeded with url: /api/v1/engulfing-pattern (Caused by NewConnectionError('<urllib3.connection.HTTPConnection object at 0x0000021AFF9EA050>: Failed to establish a new connection: [WinError 10061] No connection could be made because the target machine actively refused it'))
2024-05-04 15:38:59,993 DEBUG Starting new HTTPS connection (1): api.bybit.com:443
2024-05-04 15:39:00,343 DEBUG https://api.bybit.com:443 "GET /v5/market/kline?category=spot&symbol=MNTUSDT&interval=30&limit=300 HTTP/1.1" 200 24831
2024-05-04 15:39:00,548 DEBUG Starting new HTTPS connection (1): api.bybit.com:443
2024-05-04 15:39:00,843 DEBUG https://api.bybit.com:443 "GET /v5/market/kline?category=spot&symbol=MNTUSDT&interval=30&limit=300 HTTP/1.1" 200 None
2024-05-04 15:39:01,422 DEBUG Starting new HTTP connection (1): 127.0.0.1:5000
2024-05-04 15:39:03,474 ERROR 30min tf   
Traceback (most recent call last):
  File "C:\Users\Andrew the master\Documents\GitHub\TraidingAlgorithm\venv\Lib\site-packages\urllib3\connection.py", line 203, in _new_conn
    sock = connection.create_connection(
           ^^^^^^^^^^^^^^^^^^^^^^^^^^^^^
  File "C:\Users\Andrew the master\Documents\GitHub\TraidingAlgorithm\venv\Lib\site-packages\urllib3\util\connection.py", line 85, in create_connection
    raise err
  File "C:\Users\Andrew the master\Documents\GitHub\TraidingAlgorithm\venv\Lib\site-packages\urllib3\util\connection.py", line 73, in create_connection
    sock.connect(sa)
ConnectionRefusedError: [WinError 10061] No connection could be made because the target machine actively refused it

The above exception was the direct cause of the following exception:

Traceback (most recent call last):
  File "C:\Users\Andrew the master\Documents\GitHub\TraidingAlgorithm\venv\Lib\site-packages\urllib3\connectionpool.py", line 790, in urlopen
    response = self._make_request(
               ^^^^^^^^^^^^^^^^^^^
  File "C:\Users\Andrew the master\Documents\GitHub\TraidingAlgorithm\venv\Lib\site-packages\urllib3\connectionpool.py", line 496, in _make_request
    conn.request(
  File "C:\Users\Andrew the master\Documents\GitHub\TraidingAlgorithm\venv\Lib\site-packages\urllib3\connection.py", line 395, in request
    self.endheaders()
  File "C:\Users\Andrew the master\AppData\Local\Programs\Python\Python311\Lib\http\client.py", line 1278, in endheaders
    self._send_output(message_body, encode_chunked=encode_chunked)
  File "C:\Users\Andrew the master\AppData\Local\Programs\Python\Python311\Lib\http\client.py", line 1038, in _send_output
    self.send(msg)
  File "C:\Users\Andrew the master\AppData\Local\Programs\Python\Python311\Lib\http\client.py", line 976, in send
    self.connect()
  File "C:\Users\Andrew the master\Documents\GitHub\TraidingAlgorithm\venv\Lib\site-packages\urllib3\connection.py", line 243, in connect
    self.sock = self._new_conn()
                ^^^^^^^^^^^^^^^^
  File "C:\Users\Andrew the master\Documents\GitHub\TraidingAlgorithm\venv\Lib\site-packages\urllib3\connection.py", line 218, in _new_conn
    raise NewConnectionError(
urllib3.exceptions.NewConnectionError: <urllib3.connection.HTTPConnection object at 0x0000021AFFB3DD10>: Failed to establish a new connection: [WinError 10061] No connection could be made because the target machine actively refused it

The above exception was the direct cause of the following exception:

Traceback (most recent call last):
  File "C:\Users\Andrew the master\Documents\GitHub\TraidingAlgorithm\venv\Lib\site-packages\requests\adapters.py", line 486, in send
    resp = conn.urlopen(
           ^^^^^^^^^^^^^
  File "C:\Users\Andrew the master\Documents\GitHub\TraidingAlgorithm\venv\Lib\site-packages\urllib3\connectionpool.py", line 844, in urlopen
    retries = retries.increment(
              ^^^^^^^^^^^^^^^^^^
  File "C:\Users\Andrew the master\Documents\GitHub\TraidingAlgorithm\venv\Lib\site-packages\urllib3\util\retry.py", line 515, in increment
    raise MaxRetryError(_pool, url, reason) from reason  # type: ignore[arg-type]
    ^^^^^^^^^^^^^^^^^^^^^^^^^^^^^^^^^^^^^^^^^^^^^^^^^^^
urllib3.exceptions.MaxRetryError: HTTPConnectionPool(host='127.0.0.1', port=5000): Max retries exceeded with url: /api/v1/engulfing-pattern (Caused by NewConnectionError('<urllib3.connection.HTTPConnection object at 0x0000021AFFB3DD10>: Failed to establish a new connection: [WinError 10061] No connection could be made because the target machine actively refused it'))

During handling of the above exception, another exception occurred:

Traceback (most recent call last):
  File "c:\Users\Andrew the master\Documents\GitHub\TraidingAlgorithm\main.py", line 888, in BTCUSDT_30min
    getAlert(dft2, '30min', 'Close', 28, 'HeikinAshi', symb)
  File "c:\Users\Andrew the master\Documents\GitHub\TraidingAlgorithm\main.py", line 278, in getAlert
    requests.post(url=url, data=data, headers=headers)
  File "C:\Users\Andrew the master\Documents\GitHub\TraidingAlgorithm\venv\Lib\site-packages\requests\api.py", line 115, in post
    return request("post", url, data=data, json=json, **kwargs)
           ^^^^^^^^^^^^^^^^^^^^^^^^^^^^^^^^^^^^^^^^^^^^^^^^^^^^
  File "C:\Users\Andrew the master\Documents\GitHub\TraidingAlgorithm\venv\Lib\site-packages\requests\api.py", line 59, in request
    return session.request(method=method, url=url, **kwargs)
           ^^^^^^^^^^^^^^^^^^^^^^^^^^^^^^^^^^^^^^^^^^^^^^^^^
  File "C:\Users\Andrew the master\Documents\GitHub\TraidingAlgorithm\venv\Lib\site-packages\requests\sessions.py", line 589, in request
    resp = self.send(prep, **send_kwargs)
           ^^^^^^^^^^^^^^^^^^^^^^^^^^^^^^
  File "C:\Users\Andrew the master\Documents\GitHub\TraidingAlgorithm\venv\Lib\site-packages\requests\sessions.py", line 703, in send
    r = adapter.send(request, **kwargs)
        ^^^^^^^^^^^^^^^^^^^^^^^^^^^^^^^
  File "C:\Users\Andrew the master\Documents\GitHub\TraidingAlgorithm\venv\Lib\site-packages\requests\adapters.py", line 519, in send
    raise ConnectionError(e, request=request)
requests.exceptions.ConnectionError: HTTPConnectionPool(host='127.0.0.1', port=5000): Max retries exceeded with url: /api/v1/engulfing-pattern (Caused by NewConnectionError('<urllib3.connection.HTTPConnection object at 0x0000021AFFB3DD10>: Failed to establish a new connection: [WinError 10061] No connection could be made because the target machine actively refused it'))
2024-05-04 15:39:03,478 DEBUG Starting new HTTPS connection (1): api.bybit.com:443
2024-05-04 15:39:03,976 DEBUG https://api.bybit.com:443 "GET /v5/market/kline?category=spot&symbol=XRPUSDT&interval=30&limit=300 HTTP/1.1" 200 24972
2024-05-04 15:39:03,984 DEBUG Starting new HTTPS connection (1): api.bybit.com:443
2024-05-04 15:39:04,284 DEBUG https://api.bybit.com:443 "GET /v5/market/kline?category=spot&symbol=XRPUSDT&interval=30&limit=300 HTTP/1.1" 200 24972
2024-05-04 15:39:04,768 DEBUG Starting new HTTP connection (1): 127.0.0.1:5000
2024-05-04 15:39:06,820 ERROR 30min tf   
Traceback (most recent call last):
  File "C:\Users\Andrew the master\Documents\GitHub\TraidingAlgorithm\venv\Lib\site-packages\urllib3\connection.py", line 203, in _new_conn
    sock = connection.create_connection(
           ^^^^^^^^^^^^^^^^^^^^^^^^^^^^^
  File "C:\Users\Andrew the master\Documents\GitHub\TraidingAlgorithm\venv\Lib\site-packages\urllib3\util\connection.py", line 85, in create_connection
    raise err
  File "C:\Users\Andrew the master\Documents\GitHub\TraidingAlgorithm\venv\Lib\site-packages\urllib3\util\connection.py", line 73, in create_connection
    sock.connect(sa)
ConnectionRefusedError: [WinError 10061] No connection could be made because the target machine actively refused it

The above exception was the direct cause of the following exception:

Traceback (most recent call last):
  File "C:\Users\Andrew the master\Documents\GitHub\TraidingAlgorithm\venv\Lib\site-packages\urllib3\connectionpool.py", line 790, in urlopen
    response = self._make_request(
               ^^^^^^^^^^^^^^^^^^^
  File "C:\Users\Andrew the master\Documents\GitHub\TraidingAlgorithm\venv\Lib\site-packages\urllib3\connectionpool.py", line 496, in _make_request
    conn.request(
  File "C:\Users\Andrew the master\Documents\GitHub\TraidingAlgorithm\venv\Lib\site-packages\urllib3\connection.py", line 395, in request
    self.endheaders()
  File "C:\Users\Andrew the master\AppData\Local\Programs\Python\Python311\Lib\http\client.py", line 1278, in endheaders
    self._send_output(message_body, encode_chunked=encode_chunked)
  File "C:\Users\Andrew the master\AppData\Local\Programs\Python\Python311\Lib\http\client.py", line 1038, in _send_output
    self.send(msg)
  File "C:\Users\Andrew the master\AppData\Local\Programs\Python\Python311\Lib\http\client.py", line 976, in send
    self.connect()
  File "C:\Users\Andrew the master\Documents\GitHub\TraidingAlgorithm\venv\Lib\site-packages\urllib3\connection.py", line 243, in connect
    self.sock = self._new_conn()
                ^^^^^^^^^^^^^^^^
  File "C:\Users\Andrew the master\Documents\GitHub\TraidingAlgorithm\venv\Lib\site-packages\urllib3\connection.py", line 218, in _new_conn
    raise NewConnectionError(
urllib3.exceptions.NewConnectionError: <urllib3.connection.HTTPConnection object at 0x0000021AFF61D6D0>: Failed to establish a new connection: [WinError 10061] No connection could be made because the target machine actively refused it

The above exception was the direct cause of the following exception:

Traceback (most recent call last):
  File "C:\Users\Andrew the master\Documents\GitHub\TraidingAlgorithm\venv\Lib\site-packages\requests\adapters.py", line 486, in send
    resp = conn.urlopen(
           ^^^^^^^^^^^^^
  File "C:\Users\Andrew the master\Documents\GitHub\TraidingAlgorithm\venv\Lib\site-packages\urllib3\connectionpool.py", line 844, in urlopen
    retries = retries.increment(
              ^^^^^^^^^^^^^^^^^^
  File "C:\Users\Andrew the master\Documents\GitHub\TraidingAlgorithm\venv\Lib\site-packages\urllib3\util\retry.py", line 515, in increment
    raise MaxRetryError(_pool, url, reason) from reason  # type: ignore[arg-type]
    ^^^^^^^^^^^^^^^^^^^^^^^^^^^^^^^^^^^^^^^^^^^^^^^^^^^
urllib3.exceptions.MaxRetryError: HTTPConnectionPool(host='127.0.0.1', port=5000): Max retries exceeded with url: /api/v1/engulfing-pattern (Caused by NewConnectionError('<urllib3.connection.HTTPConnection object at 0x0000021AFF61D6D0>: Failed to establish a new connection: [WinError 10061] No connection could be made because the target machine actively refused it'))

During handling of the above exception, another exception occurred:

Traceback (most recent call last):
  File "c:\Users\Andrew the master\Documents\GitHub\TraidingAlgorithm\main.py", line 888, in BTCUSDT_30min
    getAlert(dft2, '30min', 'Close', 28, 'HeikinAshi', symb)
  File "c:\Users\Andrew the master\Documents\GitHub\TraidingAlgorithm\main.py", line 483, in getAlert
    requests.post(url=url, data=data, headers=headers)
  File "C:\Users\Andrew the master\Documents\GitHub\TraidingAlgorithm\venv\Lib\site-packages\requests\api.py", line 115, in post
    return request("post", url, data=data, json=json, **kwargs)
           ^^^^^^^^^^^^^^^^^^^^^^^^^^^^^^^^^^^^^^^^^^^^^^^^^^^^
  File "C:\Users\Andrew the master\Documents\GitHub\TraidingAlgorithm\venv\Lib\site-packages\requests\api.py", line 59, in request
    return session.request(method=method, url=url, **kwargs)
           ^^^^^^^^^^^^^^^^^^^^^^^^^^^^^^^^^^^^^^^^^^^^^^^^^
  File "C:\Users\Andrew the master\Documents\GitHub\TraidingAlgorithm\venv\Lib\site-packages\requests\sessions.py", line 589, in request
    resp = self.send(prep, **send_kwargs)
           ^^^^^^^^^^^^^^^^^^^^^^^^^^^^^^
  File "C:\Users\Andrew the master\Documents\GitHub\TraidingAlgorithm\venv\Lib\site-packages\requests\sessions.py", line 703, in send
    r = adapter.send(request, **kwargs)
        ^^^^^^^^^^^^^^^^^^^^^^^^^^^^^^^
  File "C:\Users\Andrew the master\Documents\GitHub\TraidingAlgorithm\venv\Lib\site-packages\requests\adapters.py", line 519, in send
    raise ConnectionError(e, request=request)
requests.exceptions.ConnectionError: HTTPConnectionPool(host='127.0.0.1', port=5000): Max retries exceeded with url: /api/v1/engulfing-pattern (Caused by NewConnectionError('<urllib3.connection.HTTPConnection object at 0x0000021AFF61D6D0>: Failed to establish a new connection: [WinError 10061] No connection could be made because the target machine actively refused it'))
2024-05-04 15:39:06,824 DEBUG Starting new HTTPS connection (1): api.bybit.com:443
2024-05-04 15:39:07,121 DEBUG https://api.bybit.com:443 "GET /v5/market/kline?category=spot&symbol=CTCUSDT&interval=30&limit=300 HTTP/1.1" 200 26357
2024-05-04 15:39:07,131 DEBUG Starting new HTTPS connection (1): api.bybit.com:443
2024-05-04 15:39:07,417 DEBUG https://api.bybit.com:443 "GET /v5/market/kline?category=spot&symbol=CTCUSDT&interval=30&limit=300 HTTP/1.1" 200 26357
2024-05-04 15:39:07,871 DEBUG Starting new HTTP connection (1): 127.0.0.1:5000
2024-05-04 15:39:09,914 ERROR 30min tf   
Traceback (most recent call last):
  File "C:\Users\Andrew the master\Documents\GitHub\TraidingAlgorithm\venv\Lib\site-packages\urllib3\connection.py", line 203, in _new_conn
    sock = connection.create_connection(
           ^^^^^^^^^^^^^^^^^^^^^^^^^^^^^
  File "C:\Users\Andrew the master\Documents\GitHub\TraidingAlgorithm\venv\Lib\site-packages\urllib3\util\connection.py", line 85, in create_connection
    raise err
  File "C:\Users\Andrew the master\Documents\GitHub\TraidingAlgorithm\venv\Lib\site-packages\urllib3\util\connection.py", line 73, in create_connection
    sock.connect(sa)
ConnectionRefusedError: [WinError 10061] No connection could be made because the target machine actively refused it

The above exception was the direct cause of the following exception:

Traceback (most recent call last):
  File "C:\Users\Andrew the master\Documents\GitHub\TraidingAlgorithm\venv\Lib\site-packages\urllib3\connectionpool.py", line 790, in urlopen
    response = self._make_request(
               ^^^^^^^^^^^^^^^^^^^
  File "C:\Users\Andrew the master\Documents\GitHub\TraidingAlgorithm\venv\Lib\site-packages\urllib3\connectionpool.py", line 496, in _make_request
    conn.request(
  File "C:\Users\Andrew the master\Documents\GitHub\TraidingAlgorithm\venv\Lib\site-packages\urllib3\connection.py", line 395, in request
    self.endheaders()
  File "C:\Users\Andrew the master\AppData\Local\Programs\Python\Python311\Lib\http\client.py", line 1278, in endheaders
    self._send_output(message_body, encode_chunked=encode_chunked)
  File "C:\Users\Andrew the master\AppData\Local\Programs\Python\Python311\Lib\http\client.py", line 1038, in _send_output
    self.send(msg)
  File "C:\Users\Andrew the master\AppData\Local\Programs\Python\Python311\Lib\http\client.py", line 976, in send
    self.connect()
  File "C:\Users\Andrew the master\Documents\GitHub\TraidingAlgorithm\venv\Lib\site-packages\urllib3\connection.py", line 243, in connect
    self.sock = self._new_conn()
                ^^^^^^^^^^^^^^^^
  File "C:\Users\Andrew the master\Documents\GitHub\TraidingAlgorithm\venv\Lib\site-packages\urllib3\connection.py", line 218, in _new_conn
    raise NewConnectionError(
urllib3.exceptions.NewConnectionError: <urllib3.connection.HTTPConnection object at 0x0000021AFFB22350>: Failed to establish a new connection: [WinError 10061] No connection could be made because the target machine actively refused it

The above exception was the direct cause of the following exception:

Traceback (most recent call last):
  File "C:\Users\Andrew the master\Documents\GitHub\TraidingAlgorithm\venv\Lib\site-packages\requests\adapters.py", line 486, in send
    resp = conn.urlopen(
           ^^^^^^^^^^^^^
  File "C:\Users\Andrew the master\Documents\GitHub\TraidingAlgorithm\venv\Lib\site-packages\urllib3\connectionpool.py", line 844, in urlopen
    retries = retries.increment(
              ^^^^^^^^^^^^^^^^^^
  File "C:\Users\Andrew the master\Documents\GitHub\TraidingAlgorithm\venv\Lib\site-packages\urllib3\util\retry.py", line 515, in increment
    raise MaxRetryError(_pool, url, reason) from reason  # type: ignore[arg-type]
    ^^^^^^^^^^^^^^^^^^^^^^^^^^^^^^^^^^^^^^^^^^^^^^^^^^^
urllib3.exceptions.MaxRetryError: HTTPConnectionPool(host='127.0.0.1', port=5000): Max retries exceeded with url: /api/v1/engulfing-pattern (Caused by NewConnectionError('<urllib3.connection.HTTPConnection object at 0x0000021AFFB22350>: Failed to establish a new connection: [WinError 10061] No connection could be made because the target machine actively refused it'))

During handling of the above exception, another exception occurred:

Traceback (most recent call last):
  File "c:\Users\Andrew the master\Documents\GitHub\TraidingAlgorithm\main.py", line 888, in BTCUSDT_30min
    getAlert(dft2, '30min', 'Close', 28, 'HeikinAshi', symb)
  File "c:\Users\Andrew the master\Documents\GitHub\TraidingAlgorithm\main.py", line 278, in getAlert
    requests.post(url=url, data=data, headers=headers)
  File "C:\Users\Andrew the master\Documents\GitHub\TraidingAlgorithm\venv\Lib\site-packages\requests\api.py", line 115, in post
    return request("post", url, data=data, json=json, **kwargs)
           ^^^^^^^^^^^^^^^^^^^^^^^^^^^^^^^^^^^^^^^^^^^^^^^^^^^^
  File "C:\Users\Andrew the master\Documents\GitHub\TraidingAlgorithm\venv\Lib\site-packages\requests\api.py", line 59, in request
    return session.request(method=method, url=url, **kwargs)
           ^^^^^^^^^^^^^^^^^^^^^^^^^^^^^^^^^^^^^^^^^^^^^^^^^
  File "C:\Users\Andrew the master\Documents\GitHub\TraidingAlgorithm\venv\Lib\site-packages\requests\sessions.py", line 589, in request
    resp = self.send(prep, **send_kwargs)
           ^^^^^^^^^^^^^^^^^^^^^^^^^^^^^^
  File "C:\Users\Andrew the master\Documents\GitHub\TraidingAlgorithm\venv\Lib\site-packages\requests\sessions.py", line 703, in send
    r = adapter.send(request, **kwargs)
        ^^^^^^^^^^^^^^^^^^^^^^^^^^^^^^^
  File "C:\Users\Andrew the master\Documents\GitHub\TraidingAlgorithm\venv\Lib\site-packages\requests\adapters.py", line 519, in send
    raise ConnectionError(e, request=request)
requests.exceptions.ConnectionError: HTTPConnectionPool(host='127.0.0.1', port=5000): Max retries exceeded with url: /api/v1/engulfing-pattern (Caused by NewConnectionError('<urllib3.connection.HTTPConnection object at 0x0000021AFFB22350>: Failed to establish a new connection: [WinError 10061] No connection could be made because the target machine actively refused it'))
2024-05-04 15:39:09,918 DEBUG Starting new HTTPS connection (1): api.bybit.com:443
2024-05-04 15:39:10,633 DEBUG https://api.bybit.com:443 "GET /v5/market/kline?category=spot&symbol=PLANETUSDT&interval=30&limit=300 HTTP/1.1" 200 31047
2024-05-04 15:39:10,849 DEBUG Starting new HTTPS connection (1): api.bybit.com:443
2024-05-04 15:39:11,133 DEBUG https://api.bybit.com:443 "GET /v5/market/kline?category=spot&symbol=PLANETUSDT&interval=30&limit=300 HTTP/1.1" 200 31047
2024-05-04 15:39:11,573 DEBUG Starting new HTTP connection (1): 127.0.0.1:5000
2024-05-04 15:39:13,624 ERROR 30min tf   
Traceback (most recent call last):
  File "C:\Users\Andrew the master\Documents\GitHub\TraidingAlgorithm\venv\Lib\site-packages\urllib3\connection.py", line 203, in _new_conn
    sock = connection.create_connection(
           ^^^^^^^^^^^^^^^^^^^^^^^^^^^^^
  File "C:\Users\Andrew the master\Documents\GitHub\TraidingAlgorithm\venv\Lib\site-packages\urllib3\util\connection.py", line 85, in create_connection
    raise err
  File "C:\Users\Andrew the master\Documents\GitHub\TraidingAlgorithm\venv\Lib\site-packages\urllib3\util\connection.py", line 73, in create_connection
    sock.connect(sa)
ConnectionRefusedError: [WinError 10061] No connection could be made because the target machine actively refused it

The above exception was the direct cause of the following exception:

Traceback (most recent call last):
  File "C:\Users\Andrew the master\Documents\GitHub\TraidingAlgorithm\venv\Lib\site-packages\urllib3\connectionpool.py", line 790, in urlopen
    response = self._make_request(
               ^^^^^^^^^^^^^^^^^^^
  File "C:\Users\Andrew the master\Documents\GitHub\TraidingAlgorithm\venv\Lib\site-packages\urllib3\connectionpool.py", line 496, in _make_request
    conn.request(
  File "C:\Users\Andrew the master\Documents\GitHub\TraidingAlgorithm\venv\Lib\site-packages\urllib3\connection.py", line 395, in request
    self.endheaders()
  File "C:\Users\Andrew the master\AppData\Local\Programs\Python\Python311\Lib\http\client.py", line 1278, in endheaders
    self._send_output(message_body, encode_chunked=encode_chunked)
  File "C:\Users\Andrew the master\AppData\Local\Programs\Python\Python311\Lib\http\client.py", line 1038, in _send_output
    self.send(msg)
  File "C:\Users\Andrew the master\AppData\Local\Programs\Python\Python311\Lib\http\client.py", line 976, in send
    self.connect()
  File "C:\Users\Andrew the master\Documents\GitHub\TraidingAlgorithm\venv\Lib\site-packages\urllib3\connection.py", line 243, in connect
    self.sock = self._new_conn()
                ^^^^^^^^^^^^^^^^
  File "C:\Users\Andrew the master\Documents\GitHub\TraidingAlgorithm\venv\Lib\site-packages\urllib3\connection.py", line 218, in _new_conn
    raise NewConnectionError(
urllib3.exceptions.NewConnectionError: <urllib3.connection.HTTPConnection object at 0x0000021AFFA4F710>: Failed to establish a new connection: [WinError 10061] No connection could be made because the target machine actively refused it

The above exception was the direct cause of the following exception:

Traceback (most recent call last):
  File "C:\Users\Andrew the master\Documents\GitHub\TraidingAlgorithm\venv\Lib\site-packages\requests\adapters.py", line 486, in send
    resp = conn.urlopen(
           ^^^^^^^^^^^^^
  File "C:\Users\Andrew the master\Documents\GitHub\TraidingAlgorithm\venv\Lib\site-packages\urllib3\connectionpool.py", line 844, in urlopen
    retries = retries.increment(
              ^^^^^^^^^^^^^^^^^^
  File "C:\Users\Andrew the master\Documents\GitHub\TraidingAlgorithm\venv\Lib\site-packages\urllib3\util\retry.py", line 515, in increment
    raise MaxRetryError(_pool, url, reason) from reason  # type: ignore[arg-type]
    ^^^^^^^^^^^^^^^^^^^^^^^^^^^^^^^^^^^^^^^^^^^^^^^^^^^
urllib3.exceptions.MaxRetryError: HTTPConnectionPool(host='127.0.0.1', port=5000): Max retries exceeded with url: /api/v1/engulfing-pattern (Caused by NewConnectionError('<urllib3.connection.HTTPConnection object at 0x0000021AFFA4F710>: Failed to establish a new connection: [WinError 10061] No connection could be made because the target machine actively refused it'))

During handling of the above exception, another exception occurred:

Traceback (most recent call last):
  File "c:\Users\Andrew the master\Documents\GitHub\TraidingAlgorithm\main.py", line 888, in BTCUSDT_30min
    getAlert(dft2, '30min', 'Close', 28, 'HeikinAshi', symb)
  File "c:\Users\Andrew the master\Documents\GitHub\TraidingAlgorithm\main.py", line 278, in getAlert
    requests.post(url=url, data=data, headers=headers)
  File "C:\Users\Andrew the master\Documents\GitHub\TraidingAlgorithm\venv\Lib\site-packages\requests\api.py", line 115, in post
    return request("post", url, data=data, json=json, **kwargs)
           ^^^^^^^^^^^^^^^^^^^^^^^^^^^^^^^^^^^^^^^^^^^^^^^^^^^^
  File "C:\Users\Andrew the master\Documents\GitHub\TraidingAlgorithm\venv\Lib\site-packages\requests\api.py", line 59, in request
    return session.request(method=method, url=url, **kwargs)
           ^^^^^^^^^^^^^^^^^^^^^^^^^^^^^^^^^^^^^^^^^^^^^^^^^
  File "C:\Users\Andrew the master\Documents\GitHub\TraidingAlgorithm\venv\Lib\site-packages\requests\sessions.py", line 589, in request
    resp = self.send(prep, **send_kwargs)
           ^^^^^^^^^^^^^^^^^^^^^^^^^^^^^^
  File "C:\Users\Andrew the master\Documents\GitHub\TraidingAlgorithm\venv\Lib\site-packages\requests\sessions.py", line 703, in send
    r = adapter.send(request, **kwargs)
        ^^^^^^^^^^^^^^^^^^^^^^^^^^^^^^^
  File "C:\Users\Andrew the master\Documents\GitHub\TraidingAlgorithm\venv\Lib\site-packages\requests\adapters.py", line 519, in send
    raise ConnectionError(e, request=request)
requests.exceptions.ConnectionError: HTTPConnectionPool(host='127.0.0.1', port=5000): Max retries exceeded with url: /api/v1/engulfing-pattern (Caused by NewConnectionError('<urllib3.connection.HTTPConnection object at 0x0000021AFFA4F710>: Failed to establish a new connection: [WinError 10061] No connection could be made because the target machine actively refused it'))
2024-05-04 15:39:13,628 DEBUG Starting new HTTPS connection (1): api.bybit.com:443
2024-05-04 15:39:14,344 DEBUG https://api.bybit.com:443 "GET /v5/market/kline?category=spot&symbol=SOLUSDT&interval=30&limit=300 HTTP/1.1" 200 24441
2024-05-04 15:39:14,557 DEBUG Starting new HTTPS connection (1): api.bybit.com:443
2024-05-04 15:39:14,859 DEBUG https://api.bybit.com:443 "GET /v5/market/kline?category=spot&symbol=SOLUSDT&interval=30&limit=300 HTTP/1.1" 200 24441
2024-05-04 15:39:15,121 DEBUG Starting new HTTP connection (1): 127.0.0.1:5000
2024-05-04 15:39:17,171 ERROR 30min tf   
Traceback (most recent call last):
  File "C:\Users\Andrew the master\Documents\GitHub\TraidingAlgorithm\venv\Lib\site-packages\urllib3\connection.py", line 203, in _new_conn
    sock = connection.create_connection(
           ^^^^^^^^^^^^^^^^^^^^^^^^^^^^^
  File "C:\Users\Andrew the master\Documents\GitHub\TraidingAlgorithm\venv\Lib\site-packages\urllib3\util\connection.py", line 85, in create_connection
    raise err
  File "C:\Users\Andrew the master\Documents\GitHub\TraidingAlgorithm\venv\Lib\site-packages\urllib3\util\connection.py", line 73, in create_connection
    sock.connect(sa)
ConnectionRefusedError: [WinError 10061] No connection could be made because the target machine actively refused it

The above exception was the direct cause of the following exception:

Traceback (most recent call last):
  File "C:\Users\Andrew the master\Documents\GitHub\TraidingAlgorithm\venv\Lib\site-packages\urllib3\connectionpool.py", line 790, in urlopen
    response = self._make_request(
               ^^^^^^^^^^^^^^^^^^^
  File "C:\Users\Andrew the master\Documents\GitHub\TraidingAlgorithm\venv\Lib\site-packages\urllib3\connectionpool.py", line 496, in _make_request
    conn.request(
  File "C:\Users\Andrew the master\Documents\GitHub\TraidingAlgorithm\venv\Lib\site-packages\urllib3\connection.py", line 395, in request
    self.endheaders()
  File "C:\Users\Andrew the master\AppData\Local\Programs\Python\Python311\Lib\http\client.py", line 1278, in endheaders
    self._send_output(message_body, encode_chunked=encode_chunked)
  File "C:\Users\Andrew the master\AppData\Local\Programs\Python\Python311\Lib\http\client.py", line 1038, in _send_output
    self.send(msg)
  File "C:\Users\Andrew the master\AppData\Local\Programs\Python\Python311\Lib\http\client.py", line 976, in send
    self.connect()
  File "C:\Users\Andrew the master\Documents\GitHub\TraidingAlgorithm\venv\Lib\site-packages\urllib3\connection.py", line 243, in connect
    self.sock = self._new_conn()
                ^^^^^^^^^^^^^^^^
  File "C:\Users\Andrew the master\Documents\GitHub\TraidingAlgorithm\venv\Lib\site-packages\urllib3\connection.py", line 218, in _new_conn
    raise NewConnectionError(
urllib3.exceptions.NewConnectionError: <urllib3.connection.HTTPConnection object at 0x0000021AFFB21890>: Failed to establish a new connection: [WinError 10061] No connection could be made because the target machine actively refused it

The above exception was the direct cause of the following exception:

Traceback (most recent call last):
  File "C:\Users\Andrew the master\Documents\GitHub\TraidingAlgorithm\venv\Lib\site-packages\requests\adapters.py", line 486, in send
    resp = conn.urlopen(
           ^^^^^^^^^^^^^
  File "C:\Users\Andrew the master\Documents\GitHub\TraidingAlgorithm\venv\Lib\site-packages\urllib3\connectionpool.py", line 844, in urlopen
    retries = retries.increment(
              ^^^^^^^^^^^^^^^^^^
  File "C:\Users\Andrew the master\Documents\GitHub\TraidingAlgorithm\venv\Lib\site-packages\urllib3\util\retry.py", line 515, in increment
    raise MaxRetryError(_pool, url, reason) from reason  # type: ignore[arg-type]
    ^^^^^^^^^^^^^^^^^^^^^^^^^^^^^^^^^^^^^^^^^^^^^^^^^^^
urllib3.exceptions.MaxRetryError: HTTPConnectionPool(host='127.0.0.1', port=5000): Max retries exceeded with url: /api/v1/engulfing-pattern (Caused by NewConnectionError('<urllib3.connection.HTTPConnection object at 0x0000021AFFB21890>: Failed to establish a new connection: [WinError 10061] No connection could be made because the target machine actively refused it'))

During handling of the above exception, another exception occurred:

Traceback (most recent call last):
  File "c:\Users\Andrew the master\Documents\GitHub\TraidingAlgorithm\main.py", line 888, in BTCUSDT_30min
    getAlert(dft2, '30min', 'Close', 28, 'HeikinAshi', symb)
  File "c:\Users\Andrew the master\Documents\GitHub\TraidingAlgorithm\main.py", line 483, in getAlert
    requests.post(url=url, data=data, headers=headers)
  File "C:\Users\Andrew the master\Documents\GitHub\TraidingAlgorithm\venv\Lib\site-packages\requests\api.py", line 115, in post
    return request("post", url, data=data, json=json, **kwargs)
           ^^^^^^^^^^^^^^^^^^^^^^^^^^^^^^^^^^^^^^^^^^^^^^^^^^^^
  File "C:\Users\Andrew the master\Documents\GitHub\TraidingAlgorithm\venv\Lib\site-packages\requests\api.py", line 59, in request
    return session.request(method=method, url=url, **kwargs)
           ^^^^^^^^^^^^^^^^^^^^^^^^^^^^^^^^^^^^^^^^^^^^^^^^^
  File "C:\Users\Andrew the master\Documents\GitHub\TraidingAlgorithm\venv\Lib\site-packages\requests\sessions.py", line 589, in request
    resp = self.send(prep, **send_kwargs)
           ^^^^^^^^^^^^^^^^^^^^^^^^^^^^^^
  File "C:\Users\Andrew the master\Documents\GitHub\TraidingAlgorithm\venv\Lib\site-packages\requests\sessions.py", line 703, in send
    r = adapter.send(request, **kwargs)
        ^^^^^^^^^^^^^^^^^^^^^^^^^^^^^^^
  File "C:\Users\Andrew the master\Documents\GitHub\TraidingAlgorithm\venv\Lib\site-packages\requests\adapters.py", line 519, in send
    raise ConnectionError(e, request=request)
requests.exceptions.ConnectionError: HTTPConnectionPool(host='127.0.0.1', port=5000): Max retries exceeded with url: /api/v1/engulfing-pattern (Caused by NewConnectionError('<urllib3.connection.HTTPConnection object at 0x0000021AFFB21890>: Failed to establish a new connection: [WinError 10061] No connection could be made because the target machine actively refused it'))
2024-05-04 15:39:17,175 DEBUG Starting new HTTPS connection (1): api.bybit.com:443
2024-05-04 15:39:17,873 DEBUG https://api.bybit.com:443 "GET /v5/market/kline?category=spot&symbol=LINKUSDT&interval=30&limit=300 HTTP/1.1" 200 25781
2024-05-04 15:39:18,083 DEBUG Starting new HTTPS connection (1): api.bybit.com:443
2024-05-04 15:39:18,996 DEBUG https://api.bybit.com:443 "GET /v5/market/kline?category=spot&symbol=LINKUSDT&interval=30&limit=300 HTTP/1.1" 200 25781
2024-05-04 15:39:19,371 DEBUG Starting new HTTP connection (1): 127.0.0.1:5000
2024-05-04 15:39:21,413 ERROR 30min tf   
Traceback (most recent call last):
  File "C:\Users\Andrew the master\Documents\GitHub\TraidingAlgorithm\venv\Lib\site-packages\urllib3\connection.py", line 203, in _new_conn
    sock = connection.create_connection(
           ^^^^^^^^^^^^^^^^^^^^^^^^^^^^^
  File "C:\Users\Andrew the master\Documents\GitHub\TraidingAlgorithm\venv\Lib\site-packages\urllib3\util\connection.py", line 85, in create_connection
    raise err
  File "C:\Users\Andrew the master\Documents\GitHub\TraidingAlgorithm\venv\Lib\site-packages\urllib3\util\connection.py", line 73, in create_connection
    sock.connect(sa)
ConnectionRefusedError: [WinError 10061] No connection could be made because the target machine actively refused it

The above exception was the direct cause of the following exception:

Traceback (most recent call last):
  File "C:\Users\Andrew the master\Documents\GitHub\TraidingAlgorithm\venv\Lib\site-packages\urllib3\connectionpool.py", line 790, in urlopen
    response = self._make_request(
               ^^^^^^^^^^^^^^^^^^^
  File "C:\Users\Andrew the master\Documents\GitHub\TraidingAlgorithm\venv\Lib\site-packages\urllib3\connectionpool.py", line 496, in _make_request
    conn.request(
  File "C:\Users\Andrew the master\Documents\GitHub\TraidingAlgorithm\venv\Lib\site-packages\urllib3\connection.py", line 395, in request
    self.endheaders()
  File "C:\Users\Andrew the master\AppData\Local\Programs\Python\Python311\Lib\http\client.py", line 1278, in endheaders
    self._send_output(message_body, encode_chunked=encode_chunked)
  File "C:\Users\Andrew the master\AppData\Local\Programs\Python\Python311\Lib\http\client.py", line 1038, in _send_output
    self.send(msg)
  File "C:\Users\Andrew the master\AppData\Local\Programs\Python\Python311\Lib\http\client.py", line 976, in send
    self.connect()
  File "C:\Users\Andrew the master\Documents\GitHub\TraidingAlgorithm\venv\Lib\site-packages\urllib3\connection.py", line 243, in connect
    self.sock = self._new_conn()
                ^^^^^^^^^^^^^^^^
  File "C:\Users\Andrew the master\Documents\GitHub\TraidingAlgorithm\venv\Lib\site-packages\urllib3\connection.py", line 218, in _new_conn
    raise NewConnectionError(
urllib3.exceptions.NewConnectionError: <urllib3.connection.HTTPConnection object at 0x0000021AFFA4F710>: Failed to establish a new connection: [WinError 10061] No connection could be made because the target machine actively refused it

The above exception was the direct cause of the following exception:

Traceback (most recent call last):
  File "C:\Users\Andrew the master\Documents\GitHub\TraidingAlgorithm\venv\Lib\site-packages\requests\adapters.py", line 486, in send
    resp = conn.urlopen(
           ^^^^^^^^^^^^^
  File "C:\Users\Andrew the master\Documents\GitHub\TraidingAlgorithm\venv\Lib\site-packages\urllib3\connectionpool.py", line 844, in urlopen
    retries = retries.increment(
              ^^^^^^^^^^^^^^^^^^
  File "C:\Users\Andrew the master\Documents\GitHub\TraidingAlgorithm\venv\Lib\site-packages\urllib3\util\retry.py", line 515, in increment
    raise MaxRetryError(_pool, url, reason) from reason  # type: ignore[arg-type]
    ^^^^^^^^^^^^^^^^^^^^^^^^^^^^^^^^^^^^^^^^^^^^^^^^^^^
urllib3.exceptions.MaxRetryError: HTTPConnectionPool(host='127.0.0.1', port=5000): Max retries exceeded with url: /api/v1/engulfing-pattern (Caused by NewConnectionError('<urllib3.connection.HTTPConnection object at 0x0000021AFFA4F710>: Failed to establish a new connection: [WinError 10061] No connection could be made because the target machine actively refused it'))

During handling of the above exception, another exception occurred:

Traceback (most recent call last):
  File "c:\Users\Andrew the master\Documents\GitHub\TraidingAlgorithm\main.py", line 888, in BTCUSDT_30min
    getAlert(dft2, '30min', 'Close', 28, 'HeikinAshi', symb)
  File "c:\Users\Andrew the master\Documents\GitHub\TraidingAlgorithm\main.py", line 278, in getAlert
    requests.post(url=url, data=data, headers=headers)
  File "C:\Users\Andrew the master\Documents\GitHub\TraidingAlgorithm\venv\Lib\site-packages\requests\api.py", line 115, in post
    return request("post", url, data=data, json=json, **kwargs)
           ^^^^^^^^^^^^^^^^^^^^^^^^^^^^^^^^^^^^^^^^^^^^^^^^^^^^
  File "C:\Users\Andrew the master\Documents\GitHub\TraidingAlgorithm\venv\Lib\site-packages\requests\api.py", line 59, in request
    return session.request(method=method, url=url, **kwargs)
           ^^^^^^^^^^^^^^^^^^^^^^^^^^^^^^^^^^^^^^^^^^^^^^^^^
  File "C:\Users\Andrew the master\Documents\GitHub\TraidingAlgorithm\venv\Lib\site-packages\requests\sessions.py", line 589, in request
    resp = self.send(prep, **send_kwargs)
           ^^^^^^^^^^^^^^^^^^^^^^^^^^^^^^
  File "C:\Users\Andrew the master\Documents\GitHub\TraidingAlgorithm\venv\Lib\site-packages\requests\sessions.py", line 703, in send
    r = adapter.send(request, **kwargs)
        ^^^^^^^^^^^^^^^^^^^^^^^^^^^^^^^
  File "C:\Users\Andrew the master\Documents\GitHub\TraidingAlgorithm\venv\Lib\site-packages\requests\adapters.py", line 519, in send
    raise ConnectionError(e, request=request)
requests.exceptions.ConnectionError: HTTPConnectionPool(host='127.0.0.1', port=5000): Max retries exceeded with url: /api/v1/engulfing-pattern (Caused by NewConnectionError('<urllib3.connection.HTTPConnection object at 0x0000021AFFA4F710>: Failed to establish a new connection: [WinError 10061] No connection could be made because the target machine actively refused it'))
2024-05-04 15:39:21,417 DEBUG Starting new HTTPS connection (1): api.bybit.com:443
2024-05-04 15:39:21,706 DEBUG https://api.bybit.com:443 "GET /v5/market/kline?category=spot&symbol=FBUSDT&interval=30&limit=300 HTTP/1.1" 200 None
2024-05-04 15:39:21,712 DEBUG Starting new HTTPS connection (1): api.bybit.com:443
2024-05-04 15:39:22,018 DEBUG https://api.bybit.com:443 "GET /v5/market/kline?category=spot&symbol=FBUSDT&interval=30&limit=300 HTTP/1.1" 200 None
2024-05-04 15:39:22,537 DEBUG Starting new HTTP connection (1): 127.0.0.1:5000
2024-05-04 15:39:24,580 ERROR 30min tf   
Traceback (most recent call last):
  File "C:\Users\Andrew the master\Documents\GitHub\TraidingAlgorithm\venv\Lib\site-packages\urllib3\connection.py", line 203, in _new_conn
    sock = connection.create_connection(
           ^^^^^^^^^^^^^^^^^^^^^^^^^^^^^
  File "C:\Users\Andrew the master\Documents\GitHub\TraidingAlgorithm\venv\Lib\site-packages\urllib3\util\connection.py", line 85, in create_connection
    raise err
  File "C:\Users\Andrew the master\Documents\GitHub\TraidingAlgorithm\venv\Lib\site-packages\urllib3\util\connection.py", line 73, in create_connection
    sock.connect(sa)
ConnectionRefusedError: [WinError 10061] No connection could be made because the target machine actively refused it

The above exception was the direct cause of the following exception:

Traceback (most recent call last):
  File "C:\Users\Andrew the master\Documents\GitHub\TraidingAlgorithm\venv\Lib\site-packages\urllib3\connectionpool.py", line 790, in urlopen
    response = self._make_request(
               ^^^^^^^^^^^^^^^^^^^
  File "C:\Users\Andrew the master\Documents\GitHub\TraidingAlgorithm\venv\Lib\site-packages\urllib3\connectionpool.py", line 496, in _make_request
    conn.request(
  File "C:\Users\Andrew the master\Documents\GitHub\TraidingAlgorithm\venv\Lib\site-packages\urllib3\connection.py", line 395, in request
    self.endheaders()
  File "C:\Users\Andrew the master\AppData\Local\Programs\Python\Python311\Lib\http\client.py", line 1278, in endheaders
    self._send_output(message_body, encode_chunked=encode_chunked)
  File "C:\Users\Andrew the master\AppData\Local\Programs\Python\Python311\Lib\http\client.py", line 1038, in _send_output
    self.send(msg)
  File "C:\Users\Andrew the master\AppData\Local\Programs\Python\Python311\Lib\http\client.py", line 976, in send
    self.connect()
  File "C:\Users\Andrew the master\Documents\GitHub\TraidingAlgorithm\venv\Lib\site-packages\urllib3\connection.py", line 243, in connect
    self.sock = self._new_conn()
                ^^^^^^^^^^^^^^^^
  File "C:\Users\Andrew the master\Documents\GitHub\TraidingAlgorithm\venv\Lib\site-packages\urllib3\connection.py", line 218, in _new_conn
    raise NewConnectionError(
urllib3.exceptions.NewConnectionError: <urllib3.connection.HTTPConnection object at 0x0000021AFFA656D0>: Failed to establish a new connection: [WinError 10061] No connection could be made because the target machine actively refused it

The above exception was the direct cause of the following exception:

Traceback (most recent call last):
  File "C:\Users\Andrew the master\Documents\GitHub\TraidingAlgorithm\venv\Lib\site-packages\requests\adapters.py", line 486, in send
    resp = conn.urlopen(
           ^^^^^^^^^^^^^
  File "C:\Users\Andrew the master\Documents\GitHub\TraidingAlgorithm\venv\Lib\site-packages\urllib3\connectionpool.py", line 844, in urlopen
    retries = retries.increment(
              ^^^^^^^^^^^^^^^^^^
  File "C:\Users\Andrew the master\Documents\GitHub\TraidingAlgorithm\venv\Lib\site-packages\urllib3\util\retry.py", line 515, in increment
    raise MaxRetryError(_pool, url, reason) from reason  # type: ignore[arg-type]
    ^^^^^^^^^^^^^^^^^^^^^^^^^^^^^^^^^^^^^^^^^^^^^^^^^^^
urllib3.exceptions.MaxRetryError: HTTPConnectionPool(host='127.0.0.1', port=5000): Max retries exceeded with url: /api/v1/engulfing-pattern (Caused by NewConnectionError('<urllib3.connection.HTTPConnection object at 0x0000021AFFA656D0>: Failed to establish a new connection: [WinError 10061] No connection could be made because the target machine actively refused it'))

During handling of the above exception, another exception occurred:

Traceback (most recent call last):
  File "c:\Users\Andrew the master\Documents\GitHub\TraidingAlgorithm\main.py", line 888, in BTCUSDT_30min
    getAlert(dft2, '30min', 'Close', 28, 'HeikinAshi', symb)
  File "c:\Users\Andrew the master\Documents\GitHub\TraidingAlgorithm\main.py", line 278, in getAlert
    requests.post(url=url, data=data, headers=headers)
  File "C:\Users\Andrew the master\Documents\GitHub\TraidingAlgorithm\venv\Lib\site-packages\requests\api.py", line 115, in post
    return request("post", url, data=data, json=json, **kwargs)
           ^^^^^^^^^^^^^^^^^^^^^^^^^^^^^^^^^^^^^^^^^^^^^^^^^^^^
  File "C:\Users\Andrew the master\Documents\GitHub\TraidingAlgorithm\venv\Lib\site-packages\requests\api.py", line 59, in request
    return session.request(method=method, url=url, **kwargs)
           ^^^^^^^^^^^^^^^^^^^^^^^^^^^^^^^^^^^^^^^^^^^^^^^^^
  File "C:\Users\Andrew the master\Documents\GitHub\TraidingAlgorithm\venv\Lib\site-packages\requests\sessions.py", line 589, in request
    resp = self.send(prep, **send_kwargs)
           ^^^^^^^^^^^^^^^^^^^^^^^^^^^^^^
  File "C:\Users\Andrew the master\Documents\GitHub\TraidingAlgorithm\venv\Lib\site-packages\requests\sessions.py", line 703, in send
    r = adapter.send(request, **kwargs)
        ^^^^^^^^^^^^^^^^^^^^^^^^^^^^^^^
  File "C:\Users\Andrew the master\Documents\GitHub\TraidingAlgorithm\venv\Lib\site-packages\requests\adapters.py", line 519, in send
    raise ConnectionError(e, request=request)
requests.exceptions.ConnectionError: HTTPConnectionPool(host='127.0.0.1', port=5000): Max retries exceeded with url: /api/v1/engulfing-pattern (Caused by NewConnectionError('<urllib3.connection.HTTPConnection object at 0x0000021AFFA656D0>: Failed to establish a new connection: [WinError 10061] No connection could be made because the target machine actively refused it'))
2024-05-04 15:39:24,584 DEBUG Starting new HTTPS connection (1): api.bybit.com:443
2024-05-04 15:39:24,888 DEBUG https://api.bybit.com:443 "GET /v5/market/kline?category=spot&symbol=APTUSDT&interval=30&limit=300 HTTP/1.1" 200 24176
2024-05-04 15:39:25,108 DEBUG Starting new HTTPS connection (1): api.bybit.com:443
2024-05-04 15:39:25,412 DEBUG https://api.bybit.com:443 "GET /v5/market/kline?category=spot&symbol=APTUSDT&interval=30&limit=300 HTTP/1.1" 200 24176
2024-05-04 15:39:25,702 DEBUG Starting new HTTP connection (1): 127.0.0.1:5000
2024-05-04 15:39:27,748 ERROR 30min tf   
Traceback (most recent call last):
  File "C:\Users\Andrew the master\Documents\GitHub\TraidingAlgorithm\venv\Lib\site-packages\urllib3\connection.py", line 203, in _new_conn
    sock = connection.create_connection(
           ^^^^^^^^^^^^^^^^^^^^^^^^^^^^^
  File "C:\Users\Andrew the master\Documents\GitHub\TraidingAlgorithm\venv\Lib\site-packages\urllib3\util\connection.py", line 85, in create_connection
    raise err
  File "C:\Users\Andrew the master\Documents\GitHub\TraidingAlgorithm\venv\Lib\site-packages\urllib3\util\connection.py", line 73, in create_connection
    sock.connect(sa)
ConnectionRefusedError: [WinError 10061] No connection could be made because the target machine actively refused it

The above exception was the direct cause of the following exception:

Traceback (most recent call last):
  File "C:\Users\Andrew the master\Documents\GitHub\TraidingAlgorithm\venv\Lib\site-packages\urllib3\connectionpool.py", line 790, in urlopen
    response = self._make_request(
               ^^^^^^^^^^^^^^^^^^^
  File "C:\Users\Andrew the master\Documents\GitHub\TraidingAlgorithm\venv\Lib\site-packages\urllib3\connectionpool.py", line 496, in _make_request
    conn.request(
  File "C:\Users\Andrew the master\Documents\GitHub\TraidingAlgorithm\venv\Lib\site-packages\urllib3\connection.py", line 395, in request
    self.endheaders()
  File "C:\Users\Andrew the master\AppData\Local\Programs\Python\Python311\Lib\http\client.py", line 1278, in endheaders
    self._send_output(message_body, encode_chunked=encode_chunked)
  File "C:\Users\Andrew the master\AppData\Local\Programs\Python\Python311\Lib\http\client.py", line 1038, in _send_output
    self.send(msg)
  File "C:\Users\Andrew the master\AppData\Local\Programs\Python\Python311\Lib\http\client.py", line 976, in send
    self.connect()
  File "C:\Users\Andrew the master\Documents\GitHub\TraidingAlgorithm\venv\Lib\site-packages\urllib3\connection.py", line 243, in connect
    self.sock = self._new_conn()
                ^^^^^^^^^^^^^^^^
  File "C:\Users\Andrew the master\Documents\GitHub\TraidingAlgorithm\venv\Lib\site-packages\urllib3\connection.py", line 218, in _new_conn
    raise NewConnectionError(
urllib3.exceptions.NewConnectionError: <urllib3.connection.HTTPConnection object at 0x0000021AFFA356D0>: Failed to establish a new connection: [WinError 10061] No connection could be made because the target machine actively refused it

The above exception was the direct cause of the following exception:

Traceback (most recent call last):
  File "C:\Users\Andrew the master\Documents\GitHub\TraidingAlgorithm\venv\Lib\site-packages\requests\adapters.py", line 486, in send
    resp = conn.urlopen(
           ^^^^^^^^^^^^^
  File "C:\Users\Andrew the master\Documents\GitHub\TraidingAlgorithm\venv\Lib\site-packages\urllib3\connectionpool.py", line 844, in urlopen
    retries = retries.increment(
              ^^^^^^^^^^^^^^^^^^
  File "C:\Users\Andrew the master\Documents\GitHub\TraidingAlgorithm\venv\Lib\site-packages\urllib3\util\retry.py", line 515, in increment
    raise MaxRetryError(_pool, url, reason) from reason  # type: ignore[arg-type]
    ^^^^^^^^^^^^^^^^^^^^^^^^^^^^^^^^^^^^^^^^^^^^^^^^^^^
urllib3.exceptions.MaxRetryError: HTTPConnectionPool(host='127.0.0.1', port=5000): Max retries exceeded with url: /api/v1/engulfing-pattern (Caused by NewConnectionError('<urllib3.connection.HTTPConnection object at 0x0000021AFFA356D0>: Failed to establish a new connection: [WinError 10061] No connection could be made because the target machine actively refused it'))

During handling of the above exception, another exception occurred:

Traceback (most recent call last):
  File "c:\Users\Andrew the master\Documents\GitHub\TraidingAlgorithm\main.py", line 888, in BTCUSDT_30min
    getAlert(dft2, '30min', 'Close', 28, 'HeikinAshi', symb)
  File "c:\Users\Andrew the master\Documents\GitHub\TraidingAlgorithm\main.py", line 483, in getAlert
    requests.post(url=url, data=data, headers=headers)
  File "C:\Users\Andrew the master\Documents\GitHub\TraidingAlgorithm\venv\Lib\site-packages\requests\api.py", line 115, in post
    return request("post", url, data=data, json=json, **kwargs)
           ^^^^^^^^^^^^^^^^^^^^^^^^^^^^^^^^^^^^^^^^^^^^^^^^^^^^
  File "C:\Users\Andrew the master\Documents\GitHub\TraidingAlgorithm\venv\Lib\site-packages\requests\api.py", line 59, in request
    return session.request(method=method, url=url, **kwargs)
           ^^^^^^^^^^^^^^^^^^^^^^^^^^^^^^^^^^^^^^^^^^^^^^^^^
  File "C:\Users\Andrew the master\Documents\GitHub\TraidingAlgorithm\venv\Lib\site-packages\requests\sessions.py", line 589, in request
    resp = self.send(prep, **send_kwargs)
           ^^^^^^^^^^^^^^^^^^^^^^^^^^^^^^
  File "C:\Users\Andrew the master\Documents\GitHub\TraidingAlgorithm\venv\Lib\site-packages\requests\sessions.py", line 703, in send
    r = adapter.send(request, **kwargs)
        ^^^^^^^^^^^^^^^^^^^^^^^^^^^^^^^
  File "C:\Users\Andrew the master\Documents\GitHub\TraidingAlgorithm\venv\Lib\site-packages\requests\adapters.py", line 519, in send
    raise ConnectionError(e, request=request)
requests.exceptions.ConnectionError: HTTPConnectionPool(host='127.0.0.1', port=5000): Max retries exceeded with url: /api/v1/engulfing-pattern (Caused by NewConnectionError('<urllib3.connection.HTTPConnection object at 0x0000021AFFA356D0>: Failed to establish a new connection: [WinError 10061] No connection could be made because the target machine actively refused it'))
2024-05-04 15:39:27,754 DEBUG Starting new HTTPS connection (1): api.bybit.com:443
2024-05-04 15:39:28,451 DEBUG https://api.bybit.com:443 "GET /v5/market/kline?category=spot&symbol=DOGEUSDT&interval=30&limit=300 HTTP/1.1" 200 25874
2024-05-04 15:39:28,660 DEBUG Starting new HTTPS connection (1): api.bybit.com:443
2024-05-04 15:39:29,576 DEBUG https://api.bybit.com:443 "GET /v5/market/kline?category=spot&symbol=DOGEUSDT&interval=30&limit=300 HTTP/1.1" 200 25874
2024-05-04 15:39:29,863 DEBUG Starting new HTTP connection (1): 127.0.0.1:5000
2024-05-04 15:39:31,916 ERROR 30min tf   
Traceback (most recent call last):
  File "C:\Users\Andrew the master\Documents\GitHub\TraidingAlgorithm\venv\Lib\site-packages\urllib3\connection.py", line 203, in _new_conn
    sock = connection.create_connection(
           ^^^^^^^^^^^^^^^^^^^^^^^^^^^^^
  File "C:\Users\Andrew the master\Documents\GitHub\TraidingAlgorithm\venv\Lib\site-packages\urllib3\util\connection.py", line 85, in create_connection
    raise err
  File "C:\Users\Andrew the master\Documents\GitHub\TraidingAlgorithm\venv\Lib\site-packages\urllib3\util\connection.py", line 73, in create_connection
    sock.connect(sa)
ConnectionRefusedError: [WinError 10061] No connection could be made because the target machine actively refused it

The above exception was the direct cause of the following exception:

Traceback (most recent call last):
  File "C:\Users\Andrew the master\Documents\GitHub\TraidingAlgorithm\venv\Lib\site-packages\urllib3\connectionpool.py", line 790, in urlopen
    response = self._make_request(
               ^^^^^^^^^^^^^^^^^^^
  File "C:\Users\Andrew the master\Documents\GitHub\TraidingAlgorithm\venv\Lib\site-packages\urllib3\connectionpool.py", line 496, in _make_request
    conn.request(
  File "C:\Users\Andrew the master\Documents\GitHub\TraidingAlgorithm\venv\Lib\site-packages\urllib3\connection.py", line 395, in request
    self.endheaders()
  File "C:\Users\Andrew the master\AppData\Local\Programs\Python\Python311\Lib\http\client.py", line 1278, in endheaders
    self._send_output(message_body, encode_chunked=encode_chunked)
  File "C:\Users\Andrew the master\AppData\Local\Programs\Python\Python311\Lib\http\client.py", line 1038, in _send_output
    self.send(msg)
  File "C:\Users\Andrew the master\AppData\Local\Programs\Python\Python311\Lib\http\client.py", line 976, in send
    self.connect()
  File "C:\Users\Andrew the master\Documents\GitHub\TraidingAlgorithm\venv\Lib\site-packages\urllib3\connection.py", line 243, in connect
    self.sock = self._new_conn()
                ^^^^^^^^^^^^^^^^
  File "C:\Users\Andrew the master\Documents\GitHub\TraidingAlgorithm\venv\Lib\site-packages\urllib3\connection.py", line 218, in _new_conn
    raise NewConnectionError(
urllib3.exceptions.NewConnectionError: <urllib3.connection.HTTPConnection object at 0x0000021AFF9DCFD0>: Failed to establish a new connection: [WinError 10061] No connection could be made because the target machine actively refused it

The above exception was the direct cause of the following exception:

Traceback (most recent call last):
  File "C:\Users\Andrew the master\Documents\GitHub\TraidingAlgorithm\venv\Lib\site-packages\requests\adapters.py", line 486, in send
    resp = conn.urlopen(
           ^^^^^^^^^^^^^
  File "C:\Users\Andrew the master\Documents\GitHub\TraidingAlgorithm\venv\Lib\site-packages\urllib3\connectionpool.py", line 844, in urlopen
    retries = retries.increment(
              ^^^^^^^^^^^^^^^^^^
  File "C:\Users\Andrew the master\Documents\GitHub\TraidingAlgorithm\venv\Lib\site-packages\urllib3\util\retry.py", line 515, in increment
    raise MaxRetryError(_pool, url, reason) from reason  # type: ignore[arg-type]
    ^^^^^^^^^^^^^^^^^^^^^^^^^^^^^^^^^^^^^^^^^^^^^^^^^^^
urllib3.exceptions.MaxRetryError: HTTPConnectionPool(host='127.0.0.1', port=5000): Max retries exceeded with url: /api/v1/engulfing-pattern (Caused by NewConnectionError('<urllib3.connection.HTTPConnection object at 0x0000021AFF9DCFD0>: Failed to establish a new connection: [WinError 10061] No connection could be made because the target machine actively refused it'))

During handling of the above exception, another exception occurred:

Traceback (most recent call last):
  File "c:\Users\Andrew the master\Documents\GitHub\TraidingAlgorithm\main.py", line 888, in BTCUSDT_30min
    getAlert(dft2, '30min', 'Close', 28, 'HeikinAshi', symb)
  File "c:\Users\Andrew the master\Documents\GitHub\TraidingAlgorithm\main.py", line 483, in getAlert
    requests.post(url=url, data=data, headers=headers)
  File "C:\Users\Andrew the master\Documents\GitHub\TraidingAlgorithm\venv\Lib\site-packages\requests\api.py", line 115, in post
    return request("post", url, data=data, json=json, **kwargs)
           ^^^^^^^^^^^^^^^^^^^^^^^^^^^^^^^^^^^^^^^^^^^^^^^^^^^^
  File "C:\Users\Andrew the master\Documents\GitHub\TraidingAlgorithm\venv\Lib\site-packages\requests\api.py", line 59, in request
    return session.request(method=method, url=url, **kwargs)
           ^^^^^^^^^^^^^^^^^^^^^^^^^^^^^^^^^^^^^^^^^^^^^^^^^
  File "C:\Users\Andrew the master\Documents\GitHub\TraidingAlgorithm\venv\Lib\site-packages\requests\sessions.py", line 589, in request
    resp = self.send(prep, **send_kwargs)
           ^^^^^^^^^^^^^^^^^^^^^^^^^^^^^^
  File "C:\Users\Andrew the master\Documents\GitHub\TraidingAlgorithm\venv\Lib\site-packages\requests\sessions.py", line 703, in send
    r = adapter.send(request, **kwargs)
        ^^^^^^^^^^^^^^^^^^^^^^^^^^^^^^^
  File "C:\Users\Andrew the master\Documents\GitHub\TraidingAlgorithm\venv\Lib\site-packages\requests\adapters.py", line 519, in send
    raise ConnectionError(e, request=request)
requests.exceptions.ConnectionError: HTTPConnectionPool(host='127.0.0.1', port=5000): Max retries exceeded with url: /api/v1/engulfing-pattern (Caused by NewConnectionError('<urllib3.connection.HTTPConnection object at 0x0000021AFF9DCFD0>: Failed to establish a new connection: [WinError 10061] No connection could be made because the target machine actively refused it'))
2024-05-04 15:39:31,919 DEBUG Starting new HTTPS connection (1): api.bybit.com:443
2024-05-04 15:39:32,673 DEBUG https://api.bybit.com:443 "GET /v5/market/kline?category=spot&symbol=TOMIUSDT&interval=30&limit=300 HTTP/1.1" 200 22417
2024-05-04 15:39:32,890 DEBUG Starting new HTTPS connection (1): api.bybit.com:443
2024-05-04 15:39:33,635 DEBUG https://api.bybit.com:443 "GET /v5/market/kline?category=spot&symbol=TOMIUSDT&interval=30&limit=300 HTTP/1.1" 200 22417
2024-05-04 15:39:34,113 DEBUG Starting new HTTP connection (1): 127.0.0.1:5000
2024-05-04 15:39:36,158 ERROR 30min tf   
Traceback (most recent call last):
  File "C:\Users\Andrew the master\Documents\GitHub\TraidingAlgorithm\venv\Lib\site-packages\urllib3\connection.py", line 203, in _new_conn
    sock = connection.create_connection(
           ^^^^^^^^^^^^^^^^^^^^^^^^^^^^^
  File "C:\Users\Andrew the master\Documents\GitHub\TraidingAlgorithm\venv\Lib\site-packages\urllib3\util\connection.py", line 85, in create_connection
    raise err
  File "C:\Users\Andrew the master\Documents\GitHub\TraidingAlgorithm\venv\Lib\site-packages\urllib3\util\connection.py", line 73, in create_connection
    sock.connect(sa)
ConnectionRefusedError: [WinError 10061] No connection could be made because the target machine actively refused it

The above exception was the direct cause of the following exception:

Traceback (most recent call last):
  File "C:\Users\Andrew the master\Documents\GitHub\TraidingAlgorithm\venv\Lib\site-packages\urllib3\connectionpool.py", line 790, in urlopen
    response = self._make_request(
               ^^^^^^^^^^^^^^^^^^^
  File "C:\Users\Andrew the master\Documents\GitHub\TraidingAlgorithm\venv\Lib\site-packages\urllib3\connectionpool.py", line 496, in _make_request
    conn.request(
  File "C:\Users\Andrew the master\Documents\GitHub\TraidingAlgorithm\venv\Lib\site-packages\urllib3\connection.py", line 395, in request
    self.endheaders()
  File "C:\Users\Andrew the master\AppData\Local\Programs\Python\Python311\Lib\http\client.py", line 1278, in endheaders
    self._send_output(message_body, encode_chunked=encode_chunked)
  File "C:\Users\Andrew the master\AppData\Local\Programs\Python\Python311\Lib\http\client.py", line 1038, in _send_output
    self.send(msg)
  File "C:\Users\Andrew the master\AppData\Local\Programs\Python\Python311\Lib\http\client.py", line 976, in send
    self.connect()
  File "C:\Users\Andrew the master\Documents\GitHub\TraidingAlgorithm\venv\Lib\site-packages\urllib3\connection.py", line 243, in connect
    self.sock = self._new_conn()
                ^^^^^^^^^^^^^^^^
  File "C:\Users\Andrew the master\Documents\GitHub\TraidingAlgorithm\venv\Lib\site-packages\urllib3\connection.py", line 218, in _new_conn
    raise NewConnectionError(
urllib3.exceptions.NewConnectionError: <urllib3.connection.HTTPConnection object at 0x0000021AFEE5F710>: Failed to establish a new connection: [WinError 10061] No connection could be made because the target machine actively refused it

The above exception was the direct cause of the following exception:

Traceback (most recent call last):
  File "C:\Users\Andrew the master\Documents\GitHub\TraidingAlgorithm\venv\Lib\site-packages\requests\adapters.py", line 486, in send
    resp = conn.urlopen(
           ^^^^^^^^^^^^^
  File "C:\Users\Andrew the master\Documents\GitHub\TraidingAlgorithm\venv\Lib\site-packages\urllib3\connectionpool.py", line 844, in urlopen
    retries = retries.increment(
              ^^^^^^^^^^^^^^^^^^
  File "C:\Users\Andrew the master\Documents\GitHub\TraidingAlgorithm\venv\Lib\site-packages\urllib3\util\retry.py", line 515, in increment
    raise MaxRetryError(_pool, url, reason) from reason  # type: ignore[arg-type]
    ^^^^^^^^^^^^^^^^^^^^^^^^^^^^^^^^^^^^^^^^^^^^^^^^^^^
urllib3.exceptions.MaxRetryError: HTTPConnectionPool(host='127.0.0.1', port=5000): Max retries exceeded with url: /api/v1/engulfing-pattern (Caused by NewConnectionError('<urllib3.connection.HTTPConnection object at 0x0000021AFEE5F710>: Failed to establish a new connection: [WinError 10061] No connection could be made because the target machine actively refused it'))

During handling of the above exception, another exception occurred:

Traceback (most recent call last):
  File "c:\Users\Andrew the master\Documents\GitHub\TraidingAlgorithm\main.py", line 888, in BTCUSDT_30min
    getAlert(dft2, '30min', 'Close', 28, 'HeikinAshi', symb)
  File "c:\Users\Andrew the master\Documents\GitHub\TraidingAlgorithm\main.py", line 278, in getAlert
    requests.post(url=url, data=data, headers=headers)
  File "C:\Users\Andrew the master\Documents\GitHub\TraidingAlgorithm\venv\Lib\site-packages\requests\api.py", line 115, in post
    return request("post", url, data=data, json=json, **kwargs)
           ^^^^^^^^^^^^^^^^^^^^^^^^^^^^^^^^^^^^^^^^^^^^^^^^^^^^
  File "C:\Users\Andrew the master\Documents\GitHub\TraidingAlgorithm\venv\Lib\site-packages\requests\api.py", line 59, in request
    return session.request(method=method, url=url, **kwargs)
           ^^^^^^^^^^^^^^^^^^^^^^^^^^^^^^^^^^^^^^^^^^^^^^^^^
  File "C:\Users\Andrew the master\Documents\GitHub\TraidingAlgorithm\venv\Lib\site-packages\requests\sessions.py", line 589, in request
    resp = self.send(prep, **send_kwargs)
           ^^^^^^^^^^^^^^^^^^^^^^^^^^^^^^
  File "C:\Users\Andrew the master\Documents\GitHub\TraidingAlgorithm\venv\Lib\site-packages\requests\sessions.py", line 703, in send
    r = adapter.send(request, **kwargs)
        ^^^^^^^^^^^^^^^^^^^^^^^^^^^^^^^
  File "C:\Users\Andrew the master\Documents\GitHub\TraidingAlgorithm\venv\Lib\site-packages\requests\adapters.py", line 519, in send
    raise ConnectionError(e, request=request)
requests.exceptions.ConnectionError: HTTPConnectionPool(host='127.0.0.1', port=5000): Max retries exceeded with url: /api/v1/engulfing-pattern (Caused by NewConnectionError('<urllib3.connection.HTTPConnection object at 0x0000021AFEE5F710>: Failed to establish a new connection: [WinError 10061] No connection could be made because the target machine actively refused it'))
2024-05-04 15:39:36,163 DEBUG Starting new HTTPS connection (1): api.bybit.com:443
2024-05-04 15:39:36,862 DEBUG https://api.bybit.com:443 "GET /v5/market/kline?category=spot&symbol=MATICUSDT&interval=30&limit=300 HTTP/1.1" 200 24516
2024-05-04 15:39:37,074 DEBUG Starting new HTTPS connection (1): api.bybit.com:443
2024-05-04 15:39:37,367 DEBUG https://api.bybit.com:443 "GET /v5/market/kline?category=spot&symbol=MATICUSDT&interval=30&limit=300 HTTP/1.1" 200 24516
2024-05-04 15:39:37,878 DEBUG Starting new HTTP connection (1): 127.0.0.1:5000
2024-05-04 15:39:39,925 ERROR 30min tf   
Traceback (most recent call last):
  File "C:\Users\Andrew the master\Documents\GitHub\TraidingAlgorithm\venv\Lib\site-packages\urllib3\connection.py", line 203, in _new_conn
    sock = connection.create_connection(
           ^^^^^^^^^^^^^^^^^^^^^^^^^^^^^
  File "C:\Users\Andrew the master\Documents\GitHub\TraidingAlgorithm\venv\Lib\site-packages\urllib3\util\connection.py", line 85, in create_connection
    raise err
  File "C:\Users\Andrew the master\Documents\GitHub\TraidingAlgorithm\venv\Lib\site-packages\urllib3\util\connection.py", line 73, in create_connection
    sock.connect(sa)
ConnectionRefusedError: [WinError 10061] No connection could be made because the target machine actively refused it

The above exception was the direct cause of the following exception:

Traceback (most recent call last):
  File "C:\Users\Andrew the master\Documents\GitHub\TraidingAlgorithm\venv\Lib\site-packages\urllib3\connectionpool.py", line 790, in urlopen
    response = self._make_request(
               ^^^^^^^^^^^^^^^^^^^
  File "C:\Users\Andrew the master\Documents\GitHub\TraidingAlgorithm\venv\Lib\site-packages\urllib3\connectionpool.py", line 496, in _make_request
    conn.request(
  File "C:\Users\Andrew the master\Documents\GitHub\TraidingAlgorithm\venv\Lib\site-packages\urllib3\connection.py", line 395, in request
    self.endheaders()
  File "C:\Users\Andrew the master\AppData\Local\Programs\Python\Python311\Lib\http\client.py", line 1278, in endheaders
    self._send_output(message_body, encode_chunked=encode_chunked)
  File "C:\Users\Andrew the master\AppData\Local\Programs\Python\Python311\Lib\http\client.py", line 1038, in _send_output
    self.send(msg)
  File "C:\Users\Andrew the master\AppData\Local\Programs\Python\Python311\Lib\http\client.py", line 976, in send
    self.connect()
  File "C:\Users\Andrew the master\Documents\GitHub\TraidingAlgorithm\venv\Lib\site-packages\urllib3\connection.py", line 243, in connect
    self.sock = self._new_conn()
                ^^^^^^^^^^^^^^^^
  File "C:\Users\Andrew the master\Documents\GitHub\TraidingAlgorithm\venv\Lib\site-packages\urllib3\connection.py", line 218, in _new_conn
    raise NewConnectionError(
urllib3.exceptions.NewConnectionError: <urllib3.connection.HTTPConnection object at 0x0000021AFF9FD6D0>: Failed to establish a new connection: [WinError 10061] No connection could be made because the target machine actively refused it

The above exception was the direct cause of the following exception:

Traceback (most recent call last):
  File "C:\Users\Andrew the master\Documents\GitHub\TraidingAlgorithm\venv\Lib\site-packages\requests\adapters.py", line 486, in send
    resp = conn.urlopen(
           ^^^^^^^^^^^^^
  File "C:\Users\Andrew the master\Documents\GitHub\TraidingAlgorithm\venv\Lib\site-packages\urllib3\connectionpool.py", line 844, in urlopen
    retries = retries.increment(
              ^^^^^^^^^^^^^^^^^^
  File "C:\Users\Andrew the master\Documents\GitHub\TraidingAlgorithm\venv\Lib\site-packages\urllib3\util\retry.py", line 515, in increment
    raise MaxRetryError(_pool, url, reason) from reason  # type: ignore[arg-type]
    ^^^^^^^^^^^^^^^^^^^^^^^^^^^^^^^^^^^^^^^^^^^^^^^^^^^
urllib3.exceptions.MaxRetryError: HTTPConnectionPool(host='127.0.0.1', port=5000): Max retries exceeded with url: /api/v1/engulfing-pattern (Caused by NewConnectionError('<urllib3.connection.HTTPConnection object at 0x0000021AFF9FD6D0>: Failed to establish a new connection: [WinError 10061] No connection could be made because the target machine actively refused it'))

During handling of the above exception, another exception occurred:

Traceback (most recent call last):
  File "c:\Users\Andrew the master\Documents\GitHub\TraidingAlgorithm\main.py", line 888, in BTCUSDT_30min
    getAlert(dft2, '30min', 'Close', 28, 'HeikinAshi', symb)
  File "c:\Users\Andrew the master\Documents\GitHub\TraidingAlgorithm\main.py", line 278, in getAlert
    requests.post(url=url, data=data, headers=headers)
  File "C:\Users\Andrew the master\Documents\GitHub\TraidingAlgorithm\venv\Lib\site-packages\requests\api.py", line 115, in post
    return request("post", url, data=data, json=json, **kwargs)
           ^^^^^^^^^^^^^^^^^^^^^^^^^^^^^^^^^^^^^^^^^^^^^^^^^^^^
  File "C:\Users\Andrew the master\Documents\GitHub\TraidingAlgorithm\venv\Lib\site-packages\requests\api.py", line 59, in request
    return session.request(method=method, url=url, **kwargs)
           ^^^^^^^^^^^^^^^^^^^^^^^^^^^^^^^^^^^^^^^^^^^^^^^^^
  File "C:\Users\Andrew the master\Documents\GitHub\TraidingAlgorithm\venv\Lib\site-packages\requests\sessions.py", line 589, in request
    resp = self.send(prep, **send_kwargs)
           ^^^^^^^^^^^^^^^^^^^^^^^^^^^^^^
  File "C:\Users\Andrew the master\Documents\GitHub\TraidingAlgorithm\venv\Lib\site-packages\requests\sessions.py", line 703, in send
    r = adapter.send(request, **kwargs)
        ^^^^^^^^^^^^^^^^^^^^^^^^^^^^^^^
  File "C:\Users\Andrew the master\Documents\GitHub\TraidingAlgorithm\venv\Lib\site-packages\requests\adapters.py", line 519, in send
    raise ConnectionError(e, request=request)
requests.exceptions.ConnectionError: HTTPConnectionPool(host='127.0.0.1', port=5000): Max retries exceeded with url: /api/v1/engulfing-pattern (Caused by NewConnectionError('<urllib3.connection.HTTPConnection object at 0x0000021AFF9FD6D0>: Failed to establish a new connection: [WinError 10061] No connection could be made because the target machine actively refused it'))
2024-05-04 15:39:39,929 DEBUG Starting new HTTPS connection (1): api.bybit.com:443
